RUNNING: "python -m dask_cuda.cli.dask_cuda_worker --rmm-pool-size=28G
             --local-directory=/tmp/
             --scheduler-file=/root/cugraph/python/cugraph-pyg/cugraph_pyg/examples/scheduler.json
             --memory-limit=auto
             --device-memory-limit=auto
            "
2023-04-04 03:56:19,258 - distributed.nanny - INFO -         Start Nanny at: 'tcp://10.120.104.11:45139'
2023-04-04 03:56:19,260 - distributed.nanny - INFO -         Start Nanny at: 'tcp://10.120.104.11:37041'
2023-04-04 03:56:20,418 - distributed.diskutils - INFO - Found stale lock file and directory '/tmp/dask-worker-space/worker-3586aryd', purging
2023-04-04 03:56:20,419 - distributed.diskutils - INFO - Found stale lock file and directory '/tmp/dask-worker-space/worker-l9ur33sd', purging
2023-04-04 03:56:20,419 - distributed.preloading - INFO - Creating preload: dask_cuda.initialize
2023-04-04 03:56:20,419 - distributed.preloading - INFO - Creating preload: dask_cuda.initialize
2023-04-04 03:56:20,419 - distributed.preloading - INFO - Import preload module: dask_cuda.initialize
2023-04-04 03:56:20,419 - distributed.preloading - INFO - Import preload module: dask_cuda.initialize
2023-04-04 03:56:20,693 - distributed.preloading - INFO - Run preload setup: dask_cuda.initialize
2023-04-04 03:56:20,696 - distributed.preloading - INFO - Run preload setup: dask_cuda.initialize
2023-04-04 03:56:23,288 - distributed.worker - INFO -       Start worker at:  tcp://10.120.104.11:38539
2023-04-04 03:56:23,288 - distributed.worker - INFO -          Listening to:  tcp://10.120.104.11:38539
2023-04-04 03:56:23,288 - distributed.worker - INFO -          dashboard at:        10.120.104.11:38387
2023-04-04 03:56:23,288 - distributed.worker - INFO - Waiting to connect to:   tcp://10.120.104.11:8786
2023-04-04 03:56:23,288 - distributed.worker - INFO - -------------------------------------------------
2023-04-04 03:56:23,288 - distributed.worker - INFO -               Threads:                          1
2023-04-04 03:56:23,288 - distributed.worker - INFO -                Memory:                 755.28 GiB
2023-04-04 03:56:23,288 - distributed.worker - INFO -       Local Directory: /tmp/dask-worker-space/worker-c5fvhifb
2023-04-04 03:56:23,288 - distributed.worker - INFO - Starting Worker plugin PreImport-73997906-58af-4fbc-91cc-dfe0ec5ff6c4
2023-04-04 03:56:23,288 - distributed.worker - INFO - Starting Worker plugin CPUAffinity-5a2ff338-9161-4c27-831c-f8f23a25e124
2023-04-04 03:56:23,289 - distributed.worker - INFO - Starting Worker plugin RMMSetup-e993e422-5f4d-4856-b976-4d006252dd7d
2023-04-04 03:56:23,293 - distributed.worker - INFO -       Start worker at:  tcp://10.120.104.11:45919
2023-04-04 03:56:23,293 - distributed.worker - INFO -          Listening to:  tcp://10.120.104.11:45919
2023-04-04 03:56:23,293 - distributed.worker - INFO -          dashboard at:        10.120.104.11:40085
2023-04-04 03:56:23,293 - distributed.worker - INFO - Waiting to connect to:   tcp://10.120.104.11:8786
2023-04-04 03:56:23,293 - distributed.worker - INFO - -------------------------------------------------
2023-04-04 03:56:23,293 - distributed.worker - INFO -               Threads:                          1
2023-04-04 03:56:23,293 - distributed.worker - INFO -                Memory:                 755.28 GiB
2023-04-04 03:56:23,294 - distributed.worker - INFO -       Local Directory: /tmp/dask-worker-space/worker-3ziu5m7e
2023-04-04 03:56:23,294 - distributed.worker - INFO - Starting Worker plugin PreImport-564e95e5-e94e-4cfb-a952-b03342416412
2023-04-04 03:56:23,294 - distributed.worker - INFO - Starting Worker plugin RMMSetup-38afbdd3-b7a2-4f4f-9aca-672af7bd8650
2023-04-04 03:56:23,455 - distributed.worker - INFO - Starting Worker plugin CPUAffinity-b91b896c-de3f-4cc6-a1be-68394e9f9023
2023-04-04 03:56:23,456 - distributed.worker - INFO - -------------------------------------------------
2023-04-04 03:56:23,456 - distributed.worker - INFO - -------------------------------------------------
2023-04-04 03:56:23,470 - distributed.worker - INFO -         Registered to:   tcp://10.120.104.11:8786
2023-04-04 03:56:23,471 - distributed.worker - INFO - -------------------------------------------------
2023-04-04 03:56:23,471 - distributed.worker - INFO -         Registered to:   tcp://10.120.104.11:8786
2023-04-04 03:56:23,472 - distributed.worker - INFO - -------------------------------------------------
2023-04-04 03:56:23,473 - distributed.core - INFO - Starting established connection to tcp://10.120.104.11:8786
2023-04-04 03:56:23,474 - distributed.core - INFO - Starting established connection to tcp://10.120.104.11:8786
2023-04-04 03:56:41,215 - distributed.worker - INFO - Run out-of-band function '_func_ucp_listener_port'
2023-04-04 03:56:41,215 - distributed.worker - INFO - Run out-of-band function '_func_ucp_listener_port'
2023-04-04 03:56:42,054 - distributed.worker - INFO - Run out-of-band function '_func_init_all'
2023-04-04 03:56:42,054 - distributed.worker - INFO - Run out-of-band function '_func_init_all'
2023-04-04 03:56:42,685 - distributed.worker - INFO - Run out-of-band function '_func_ucp_listener_port'
2023-04-04 03:56:42,697 - distributed.worker - INFO - Run out-of-band function '_func_ucp_listener_port'
2023-04-04 03:56:42,706 - distributed.worker - INFO - Run out-of-band function '_func_init_all'
2023-04-04 03:56:42,712 - distributed.worker - INFO - Run out-of-band function '_func_init_all'
2023-04-04 03:56:50,991 - distributed.worker - INFO - Run out-of-band function '_subcomm_init'
2023-04-04 03:56:51,001 - distributed.worker - INFO - Run out-of-band function '_subcomm_init'
2023-04-04 03:56:57,701 - distributed.core - INFO - Event loop was unresponsive in Worker for 14.80s.  This is often caused by long-running GIL-holding functions or moving large chunks of data. This can cause timeouts and instability.
2023-04-04 03:56:57,705 - distributed.core - INFO - Event loop was unresponsive in Worker for 14.80s.  This is often caused by long-running GIL-holding functions or moving large chunks of data. This can cause timeouts and instability.
2023-04-04 03:56:57,714 - distributed.worker - INFO - Run out-of-band function '_subcomm_init'
2023-04-04 03:56:57,714 - distributed.worker - INFO - Run out-of-band function '_subcomm_init'
2023-04-04 03:57:07,578 - distributed.worker - INFO - Run out-of-band function '_func_ucp_listener_port'
2023-04-04 03:57:07,579 - distributed.worker - INFO - Run out-of-band function '_func_ucp_listener_port'
2023-04-04 03:58:03,096 - distributed.nanny - INFO - Closing Nanny at 'tcp://10.120.104.11:45139'. Reason: nanny-close
2023-04-04 03:58:03,096 - distributed.worker - INFO - Stopping worker at tcp://10.120.104.11:38539. Reason: worker-handle-scheduler-connection-broken
2023-04-04 03:58:03,096 - distributed.worker - INFO - Stopping worker at tcp://10.120.104.11:45919. Reason: worker-close
2023-04-04 03:58:03,096 - distributed.nanny - INFO - Nanny asking worker to close. Reason: nanny-close
2023-04-04 03:58:03,097 - distributed.nanny - INFO - Closing Nanny at 'tcp://10.120.104.11:37041'. Reason: nanny-close
2023-04-04 03:58:03,098 - distributed.nanny - INFO - Nanny asking worker to close. Reason: nanny-close
2023-04-04 03:58:03,097 - distributed.batched - INFO - Batched Comm Closed <TCP (closed) Worker->Scheduler local=tcp://10.120.104.11:43116 remote=tcp://10.120.104.11:8786>
Traceback (most recent call last):
  File "/opt/conda/envs/rapids/lib/python3.10/asyncio/runners.py", line 44, in run
    return loop.run_until_complete(main)
  File "/opt/conda/envs/rapids/lib/python3.10/asyncio/base_events.py", line 636, in run_until_complete
    self.run_forever()
  File "/opt/conda/envs/rapids/lib/python3.10/asyncio/base_events.py", line 603, in run_forever
    self._run_once()
  File "/opt/conda/envs/rapids/lib/python3.10/asyncio/base_events.py", line 1868, in _run_once
    event_list = self._selector.select(timeout)
  File "/opt/conda/envs/rapids/lib/python3.10/selectors.py", line 469, in select
    fd_event_list = self._selector.poll(timeout, max_ev)
KeyboardInterrupt

During handling of the above exception, another exception occurred:

Traceback (most recent call last):
  File "/opt/conda/envs/rapids/lib/python3.10/site-packages/distributed/batched.py", line 115, in _background_send
    nbytes = yield coro
  File "/opt/conda/envs/rapids/lib/python3.10/site-packages/tornado/gen.py", line 769, in run
    value = future.result()
  File "/opt/conda/envs/rapids/lib/python3.10/site-packages/distributed/comm/tcp.py", line 269, in write
    raise CommClosedError()
distributed.comm.core.CommClosedError
2023-04-04 03:58:03,123 - distributed.worker - ERROR - Timed out during handshake while connecting to tcp://10.120.104.11:37041 after 100 s
Traceback (most recent call last):
  File "/opt/conda/envs/rapids/lib/python3.10/asyncio/runners.py", line 44, in run
    return loop.run_until_complete(main)
  File "/opt/conda/envs/rapids/lib/python3.10/asyncio/base_events.py", line 636, in run_until_complete
    self.run_forever()
  File "/opt/conda/envs/rapids/lib/python3.10/asyncio/base_events.py", line 603, in run_forever
    self._run_once()
  File "/opt/conda/envs/rapids/lib/python3.10/asyncio/base_events.py", line 1868, in _run_once
    event_list = self._selector.select(timeout)
  File "/opt/conda/envs/rapids/lib/python3.10/selectors.py", line 469, in select
    fd_event_list = self._selector.poll(timeout, max_ev)
KeyboardInterrupt

During handling of the above exception, another exception occurred:

Traceback (most recent call last):
  File "/opt/conda/envs/rapids/lib/python3.10/site-packages/tornado/iostream.py", line 869, in _read_to_buffer
    bytes_read = self.read_from_fd(buf)
  File "/opt/conda/envs/rapids/lib/python3.10/site-packages/tornado/iostream.py", line 1138, in read_from_fd
    return self.socket.recv_into(buf, len(buf))
ConnectionResetError: [Errno 104] Connection reset by peer

The above exception was the direct cause of the following exception:

Traceback (most recent call last):
  File "/opt/conda/envs/rapids/lib/python3.10/site-packages/distributed/comm/core.py", line 329, in connect
    handshake = await wait_for(comm.read(), time_left())
  File "/opt/conda/envs/rapids/lib/python3.10/site-packages/distributed/utils.py", line 1849, in wait_for
    return await asyncio.wait_for(fut, timeout)
  File "/opt/conda/envs/rapids/lib/python3.10/asyncio/tasks.py", line 445, in wait_for
    return fut.result()
  File "/opt/conda/envs/rapids/lib/python3.10/site-packages/distributed/comm/tcp.py", line 241, in read
    convert_stream_closed_error(self, e)
  File "/opt/conda/envs/rapids/lib/python3.10/site-packages/distributed/comm/tcp.py", line 142, in convert_stream_closed_error
    raise CommClosedError(f"in {obj}: {exc.__class__.__name__}: {exc}") from exc
distributed.comm.core.CommClosedError: in <TCP (closed)  local=tcp://10.120.104.11:57100 remote=tcp://10.120.104.11:37041>: ConnectionResetError: [Errno 104] Connection reset by peer

The above exception was the direct cause of the following exception:

Traceback (most recent call last):
  File "/opt/conda/envs/rapids/lib/python3.10/site-packages/distributed/utils.py", line 752, in wrapper
    return await func(*args, **kwargs)
  File "/opt/conda/envs/rapids/lib/python3.10/site-packages/distributed/worker.py", line 1573, in close
    await r.close_gracefully(reason=reason)
  File "/opt/conda/envs/rapids/lib/python3.10/site-packages/distributed/core.py", line 1262, in send_recv_from_rpc
    comm = await self.pool.connect(self.addr)
  File "/opt/conda/envs/rapids/lib/python3.10/site-packages/distributed/core.py", line 1506, in connect
    return await connect_attempt
  File "/opt/conda/envs/rapids/lib/python3.10/site-packages/distributed/core.py", line 1427, in _connect
    comm = await connect(
  File "/opt/conda/envs/rapids/lib/python3.10/site-packages/distributed/comm/core.py", line 334, in connect
    raise OSError(
OSError: Timed out during handshake while connecting to tcp://10.120.104.11:37041 after 100 s
2023-04-04 03:58:06,299 - distributed.nanny - WARNING - Worker process still alive after 3.1999961853027346 seconds, killing
2023-04-04 03:58:06,300 - distributed.nanny - WARNING - Worker process still alive after 3.199999389648438 seconds, killing
2023-04-04 03:58:07,097 - distributed.nanny - ERROR - Error in Nanny killing Worker subprocess
Traceback (most recent call last):
  File "/opt/conda/envs/rapids/lib/python3.10/asyncio/tasks.py", line 456, in wait_for
    return fut.result()
asyncio.exceptions.CancelledError

The above exception was the direct cause of the following exception:

Traceback (most recent call last):
  File "/opt/conda/envs/rapids/lib/python3.10/site-packages/distributed/nanny.py", line 607, in close
    await self.kill(timeout=timeout, reason=reason)
  File "/opt/conda/envs/rapids/lib/python3.10/site-packages/distributed/nanny.py", line 390, in kill
    await self.process.kill(reason=reason, timeout=0.8 * (deadline - time()))
  File "/opt/conda/envs/rapids/lib/python3.10/site-packages/distributed/nanny.py", line 844, in kill
    await process.join(max(0, deadline - time()))
  File "/opt/conda/envs/rapids/lib/python3.10/site-packages/distributed/process.py", line 330, in join
    await wait_for(asyncio.shield(self._exit_future), timeout)
  File "/opt/conda/envs/rapids/lib/python3.10/site-packages/distributed/utils.py", line 1849, in wait_for
    return await asyncio.wait_for(fut, timeout)
  File "/opt/conda/envs/rapids/lib/python3.10/asyncio/tasks.py", line 458, in wait_for
    raise exceptions.TimeoutError() from exc
asyncio.exceptions.TimeoutError
2023-04-04 03:58:07,099 - distributed.nanny - ERROR - Error in Nanny killing Worker subprocess
Traceback (most recent call last):
  File "/opt/conda/envs/rapids/lib/python3.10/asyncio/tasks.py", line 456, in wait_for
    return fut.result()
asyncio.exceptions.CancelledError

The above exception was the direct cause of the following exception:

Traceback (most recent call last):
  File "/opt/conda/envs/rapids/lib/python3.10/site-packages/distributed/nanny.py", line 607, in close
    await self.kill(timeout=timeout, reason=reason)
  File "/opt/conda/envs/rapids/lib/python3.10/site-packages/distributed/nanny.py", line 390, in kill
    await self.process.kill(reason=reason, timeout=0.8 * (deadline - time()))
  File "/opt/conda/envs/rapids/lib/python3.10/site-packages/distributed/nanny.py", line 844, in kill
    await process.join(max(0, deadline - time()))
  File "/opt/conda/envs/rapids/lib/python3.10/site-packages/distributed/process.py", line 330, in join
    await wait_for(asyncio.shield(self._exit_future), timeout)
  File "/opt/conda/envs/rapids/lib/python3.10/site-packages/distributed/utils.py", line 1849, in wait_for
    return await asyncio.wait_for(fut, timeout)
  File "/opt/conda/envs/rapids/lib/python3.10/asyncio/tasks.py", line 458, in wait_for
    raise exceptions.TimeoutError() from exc
asyncio.exceptions.TimeoutError
2023-04-04 03:58:07,100 - distributed.process - INFO - reaping stray process <SpawnProcess name='Dask Worker process (from Nanny)' pid=1176854 parent=1176819 started daemon>
2023-04-04 03:58:07,100 - distributed.process - INFO - reaping stray process <SpawnProcess name='Dask Worker process (from Nanny)' pid=1176851 parent=1176819 started daemon>
2023-04-04 03:58:07,336 - distributed.process - WARNING - [<AsyncProcess Dask Worker process (from Nanny)>] process 1176854 exit status was already read will report exitcode 255
2023-04-04 03:58:07,704 - distributed.process - WARNING - [<AsyncProcess Dask Worker process (from Nanny)>] process 1176851 exit status was already read will report exitcode 255
