RUNNING: "python -m dask_cuda.cli.dask_cuda_worker --rmm-pool-size=28G
             --local-directory=/tmp/
             --scheduler-file=/root/cugraph/python/cugraph-pyg/cugraph_pyg/examples/scheduler.json
             --memory-limit=auto
             --device-memory-limit=auto
            "
2023-04-04 04:10:12,833 - distributed.nanny - INFO -         Start Nanny at: 'tcp://10.120.104.11:35973'
2023-04-04 04:10:12,835 - distributed.nanny - INFO -         Start Nanny at: 'tcp://10.120.104.11:46051'
2023-04-04 04:10:13,997 - distributed.diskutils - INFO - Found stale lock file and directory '/tmp/dask-worker-space/worker-8pak7kyt', purging
2023-04-04 04:10:13,997 - distributed.diskutils - INFO - Found stale lock file and directory '/tmp/dask-worker-space/worker-c80wt2ma', purging
2023-04-04 04:10:13,998 - distributed.preloading - INFO - Creating preload: dask_cuda.initialize
2023-04-04 04:10:13,998 - distributed.preloading - INFO - Import preload module: dask_cuda.initialize
2023-04-04 04:10:14,011 - distributed.preloading - INFO - Creating preload: dask_cuda.initialize
2023-04-04 04:10:14,011 - distributed.preloading - INFO - Import preload module: dask_cuda.initialize
2023-04-04 04:10:14,280 - distributed.preloading - INFO - Run preload setup: dask_cuda.initialize
2023-04-04 04:10:14,313 - distributed.preloading - INFO - Run preload setup: dask_cuda.initialize
2023-04-04 04:10:16,141 - distributed.worker - INFO -       Start worker at:  tcp://10.120.104.11:41505
2023-04-04 04:10:16,141 - distributed.worker - INFO -          Listening to:  tcp://10.120.104.11:41505
2023-04-04 04:10:16,141 - distributed.worker - INFO -          dashboard at:        10.120.104.11:36113
2023-04-04 04:10:16,141 - distributed.worker - INFO - Waiting to connect to:   tcp://10.120.104.11:8786
2023-04-04 04:10:16,141 - distributed.worker - INFO - -------------------------------------------------
2023-04-04 04:10:16,141 - distributed.worker - INFO -               Threads:                          1
2023-04-04 04:10:16,141 - distributed.worker - INFO -                Memory:                 755.28 GiB
2023-04-04 04:10:16,141 - distributed.worker - INFO -       Local Directory: /tmp/dask-worker-space/worker-silao_99
2023-04-04 04:10:16,142 - distributed.worker - INFO - Starting Worker plugin CPUAffinity-479e60fa-33e4-4b52-9740-e1e98a234734
2023-04-04 04:10:16,142 - distributed.worker - INFO - Starting Worker plugin PreImport-a17a08a1-2244-4156-838f-4fc6f519db89
2023-04-04 04:10:16,142 - distributed.worker - INFO - Starting Worker plugin RMMSetup-ee02a4f4-112d-453a-b0b2-c721ac99c770
2023-04-04 04:10:16,161 - distributed.worker - INFO -       Start worker at:  tcp://10.120.104.11:33365
2023-04-04 04:10:16,162 - distributed.worker - INFO -          Listening to:  tcp://10.120.104.11:33365
2023-04-04 04:10:16,162 - distributed.worker - INFO -          dashboard at:        10.120.104.11:46391
2023-04-04 04:10:16,162 - distributed.worker - INFO - Waiting to connect to:   tcp://10.120.104.11:8786
2023-04-04 04:10:16,162 - distributed.worker - INFO - -------------------------------------------------
2023-04-04 04:10:16,162 - distributed.worker - INFO -               Threads:                          1
2023-04-04 04:10:16,162 - distributed.worker - INFO -                Memory:                 755.28 GiB
2023-04-04 04:10:16,162 - distributed.worker - INFO -       Local Directory: /tmp/dask-worker-space/worker-l8f7ygbl
2023-04-04 04:10:16,163 - distributed.worker - INFO - Starting Worker plugin CPUAffinity-e4ce266a-c124-450b-a469-91d825a4783b
2023-04-04 04:10:16,163 - distributed.worker - INFO - Starting Worker plugin RMMSetup-16ed3d7a-c9f2-47f3-931c-08c7c1a88d0a
2023-04-04 04:10:16,281 - distributed.worker - INFO - -------------------------------------------------
2023-04-04 04:10:16,291 - distributed.worker - INFO -         Registered to:   tcp://10.120.104.11:8786
2023-04-04 04:10:16,291 - distributed.worker - INFO - -------------------------------------------------
2023-04-04 04:10:16,293 - distributed.core - INFO - Starting established connection to tcp://10.120.104.11:8786
2023-04-04 04:10:16,321 - distributed.worker - INFO - Starting Worker plugin PreImport-7e93e3ae-1941-4d0e-9bc5-05e72305ac29
2023-04-04 04:10:16,322 - distributed.worker - INFO - -------------------------------------------------
2023-04-04 04:10:16,332 - distributed.worker - INFO -         Registered to:   tcp://10.120.104.11:8786
2023-04-04 04:10:16,332 - distributed.worker - INFO - -------------------------------------------------
2023-04-04 04:10:16,334 - distributed.core - INFO - Starting established connection to tcp://10.120.104.11:8786
2023-04-04 04:10:33,105 - distributed.worker - INFO - Run out-of-band function '_func_ucp_listener_port'
2023-04-04 04:10:33,107 - distributed.worker - INFO - Run out-of-band function '_func_ucp_listener_port'
2023-04-04 04:10:33,954 - distributed.worker - INFO - Run out-of-band function '_func_init_all'
2023-04-04 04:10:33,954 - distributed.worker - INFO - Run out-of-band function '_func_init_all'
2023-04-04 04:10:34,584 - distributed.worker - INFO - Run out-of-band function '_func_ucp_listener_port'
2023-04-04 04:10:34,590 - distributed.worker - INFO - Run out-of-band function '_func_ucp_listener_port'
2023-04-04 04:10:34,596 - distributed.worker - INFO - Run out-of-band function '_func_init_all'
2023-04-04 04:10:34,598 - distributed.worker - INFO - Run out-of-band function '_func_init_all'
2023-04-04 04:10:42,994 - distributed.worker - INFO - Run out-of-band function '_subcomm_init'
2023-04-04 04:10:43,083 - distributed.worker - INFO - Run out-of-band function '_subcomm_init'
2023-04-04 04:10:49,942 - distributed.core - INFO - Event loop was unresponsive in Worker for 15.13s.  This is often caused by long-running GIL-holding functions or moving large chunks of data. This can cause timeouts and instability.
2023-04-04 04:10:49,943 - distributed.core - INFO - Event loop was unresponsive in Worker for 15.13s.  This is often caused by long-running GIL-holding functions or moving large chunks of data. This can cause timeouts and instability.
2023-04-04 04:10:49,949 - distributed.worker - INFO - Run out-of-band function '_subcomm_init'
2023-04-04 04:10:49,949 - distributed.worker - INFO - Run out-of-band function '_subcomm_init'
2023-04-04 04:10:59,918 - distributed.worker - INFO - Run out-of-band function '_func_ucp_listener_port'
2023-04-04 04:10:59,919 - distributed.worker - INFO - Run out-of-band function '_func_ucp_listener_port'
2023-04-04 04:14:21,587 - distributed.worker - INFO - Stopping worker at tcp://10.120.104.11:33365. Reason: worker-handle-scheduler-connection-broken
2023-04-04 04:14:21,587 - distributed.nanny - INFO - Closing Nanny at 'tcp://10.120.104.11:35973'. Reason: nanny-close
2023-04-04 04:14:21,587 - distributed.worker - INFO - Stopping worker at tcp://10.120.104.11:41505. Reason: worker-close
2023-04-04 04:14:21,587 - distributed.nanny - INFO - Nanny asking worker to close. Reason: nanny-close
2023-04-04 04:14:21,588 - distributed.nanny - INFO - Closing Nanny at 'tcp://10.120.104.11:46051'. Reason: nanny-close
2023-04-04 04:14:21,589 - distributed.nanny - INFO - Nanny asking worker to close. Reason: nanny-close
2023-04-04 04:14:21,588 - distributed.batched - INFO - Batched Comm Closed <TCP (closed) Worker->Scheduler local=tcp://10.120.104.11:36150 remote=tcp://10.120.104.11:8786>
Traceback (most recent call last):
  File "/opt/conda/envs/rapids/lib/python3.10/asyncio/runners.py", line 44, in run
    return loop.run_until_complete(main)
  File "/opt/conda/envs/rapids/lib/python3.10/asyncio/base_events.py", line 636, in run_until_complete
    self.run_forever()
  File "/opt/conda/envs/rapids/lib/python3.10/asyncio/base_events.py", line 603, in run_forever
    self._run_once()
  File "/opt/conda/envs/rapids/lib/python3.10/asyncio/base_events.py", line 1868, in _run_once
    event_list = self._selector.select(timeout)
  File "/opt/conda/envs/rapids/lib/python3.10/selectors.py", line 469, in select
    fd_event_list = self._selector.poll(timeout, max_ev)
KeyboardInterrupt

During handling of the above exception, another exception occurred:

Traceback (most recent call last):
  File "/opt/conda/envs/rapids/lib/python3.10/site-packages/distributed/batched.py", line 115, in _background_send
    nbytes = yield coro
  File "/opt/conda/envs/rapids/lib/python3.10/site-packages/tornado/gen.py", line 769, in run
    value = future.result()
  File "/opt/conda/envs/rapids/lib/python3.10/site-packages/distributed/comm/tcp.py", line 269, in write
    raise CommClosedError()
distributed.comm.core.CommClosedError
2023-04-04 04:14:21,614 - distributed.worker - ERROR - Timed out during handshake while connecting to tcp://10.120.104.11:46051 after 100 s
Traceback (most recent call last):
  File "/opt/conda/envs/rapids/lib/python3.10/asyncio/runners.py", line 44, in run
    return loop.run_until_complete(main)
  File "/opt/conda/envs/rapids/lib/python3.10/asyncio/base_events.py", line 636, in run_until_complete
    self.run_forever()
  File "/opt/conda/envs/rapids/lib/python3.10/asyncio/base_events.py", line 603, in run_forever
    self._run_once()
  File "/opt/conda/envs/rapids/lib/python3.10/asyncio/base_events.py", line 1868, in _run_once
    event_list = self._selector.select(timeout)
  File "/opt/conda/envs/rapids/lib/python3.10/selectors.py", line 469, in select
    fd_event_list = self._selector.poll(timeout, max_ev)
KeyboardInterrupt

During handling of the above exception, another exception occurred:

Traceback (most recent call last):
  File "/opt/conda/envs/rapids/lib/python3.10/site-packages/tornado/iostream.py", line 869, in _read_to_buffer
    bytes_read = self.read_from_fd(buf)
  File "/opt/conda/envs/rapids/lib/python3.10/site-packages/tornado/iostream.py", line 1138, in read_from_fd
    return self.socket.recv_into(buf, len(buf))
ConnectionResetError: [Errno 104] Connection reset by peer

The above exception was the direct cause of the following exception:

Traceback (most recent call last):
  File "/opt/conda/envs/rapids/lib/python3.10/site-packages/distributed/comm/core.py", line 329, in connect
    handshake = await wait_for(comm.read(), time_left())
  File "/opt/conda/envs/rapids/lib/python3.10/site-packages/distributed/utils.py", line 1849, in wait_for
    return await asyncio.wait_for(fut, timeout)
  File "/opt/conda/envs/rapids/lib/python3.10/asyncio/tasks.py", line 445, in wait_for
    return fut.result()
  File "/opt/conda/envs/rapids/lib/python3.10/site-packages/distributed/comm/tcp.py", line 241, in read
    convert_stream_closed_error(self, e)
  File "/opt/conda/envs/rapids/lib/python3.10/site-packages/distributed/comm/tcp.py", line 142, in convert_stream_closed_error
    raise CommClosedError(f"in {obj}: {exc.__class__.__name__}: {exc}") from exc
distributed.comm.core.CommClosedError: in <TCP (closed)  local=tcp://10.120.104.11:35274 remote=tcp://10.120.104.11:46051>: ConnectionResetError: [Errno 104] Connection reset by peer

The above exception was the direct cause of the following exception:

Traceback (most recent call last):
  File "/opt/conda/envs/rapids/lib/python3.10/site-packages/distributed/utils.py", line 752, in wrapper
    return await func(*args, **kwargs)
  File "/opt/conda/envs/rapids/lib/python3.10/site-packages/distributed/worker.py", line 1573, in close
    await r.close_gracefully(reason=reason)
  File "/opt/conda/envs/rapids/lib/python3.10/site-packages/distributed/core.py", line 1262, in send_recv_from_rpc
    comm = await self.pool.connect(self.addr)
  File "/opt/conda/envs/rapids/lib/python3.10/site-packages/distributed/core.py", line 1506, in connect
    return await connect_attempt
  File "/opt/conda/envs/rapids/lib/python3.10/site-packages/distributed/core.py", line 1427, in _connect
    comm = await connect(
  File "/opt/conda/envs/rapids/lib/python3.10/site-packages/distributed/comm/core.py", line 334, in connect
    raise OSError(
OSError: Timed out during handshake while connecting to tcp://10.120.104.11:46051 after 100 s
2023-04-04 04:14:24,789 - distributed.nanny - WARNING - Worker process still alive after 3.1999949645996097 seconds, killing
2023-04-04 04:14:24,790 - distributed.nanny - WARNING - Worker process still alive after 3.199999389648438 seconds, killing
2023-04-04 04:14:25,588 - distributed.nanny - ERROR - Error in Nanny killing Worker subprocess
Traceback (most recent call last):
  File "/opt/conda/envs/rapids/lib/python3.10/asyncio/tasks.py", line 456, in wait_for
    return fut.result()
asyncio.exceptions.CancelledError

The above exception was the direct cause of the following exception:

Traceback (most recent call last):
  File "/opt/conda/envs/rapids/lib/python3.10/site-packages/distributed/nanny.py", line 607, in close
    await self.kill(timeout=timeout, reason=reason)
  File "/opt/conda/envs/rapids/lib/python3.10/site-packages/distributed/nanny.py", line 390, in kill
    await self.process.kill(reason=reason, timeout=0.8 * (deadline - time()))
  File "/opt/conda/envs/rapids/lib/python3.10/site-packages/distributed/nanny.py", line 844, in kill
    await process.join(max(0, deadline - time()))
  File "/opt/conda/envs/rapids/lib/python3.10/site-packages/distributed/process.py", line 330, in join
    await wait_for(asyncio.shield(self._exit_future), timeout)
  File "/opt/conda/envs/rapids/lib/python3.10/site-packages/distributed/utils.py", line 1849, in wait_for
    return await asyncio.wait_for(fut, timeout)
  File "/opt/conda/envs/rapids/lib/python3.10/asyncio/tasks.py", line 458, in wait_for
    raise exceptions.TimeoutError() from exc
asyncio.exceptions.TimeoutError
2023-04-04 04:14:25,590 - distributed.nanny - ERROR - Error in Nanny killing Worker subprocess
Traceback (most recent call last):
  File "/opt/conda/envs/rapids/lib/python3.10/asyncio/tasks.py", line 456, in wait_for
    return fut.result()
asyncio.exceptions.CancelledError

The above exception was the direct cause of the following exception:

Traceback (most recent call last):
  File "/opt/conda/envs/rapids/lib/python3.10/site-packages/distributed/nanny.py", line 607, in close
    await self.kill(timeout=timeout, reason=reason)
  File "/opt/conda/envs/rapids/lib/python3.10/site-packages/distributed/nanny.py", line 390, in kill
    await self.process.kill(reason=reason, timeout=0.8 * (deadline - time()))
  File "/opt/conda/envs/rapids/lib/python3.10/site-packages/distributed/nanny.py", line 844, in kill
    await process.join(max(0, deadline - time()))
  File "/opt/conda/envs/rapids/lib/python3.10/site-packages/distributed/process.py", line 330, in join
    await wait_for(asyncio.shield(self._exit_future), timeout)
  File "/opt/conda/envs/rapids/lib/python3.10/site-packages/distributed/utils.py", line 1849, in wait_for
    return await asyncio.wait_for(fut, timeout)
  File "/opt/conda/envs/rapids/lib/python3.10/asyncio/tasks.py", line 458, in wait_for
    raise exceptions.TimeoutError() from exc
asyncio.exceptions.TimeoutError
2023-04-04 04:14:25,591 - distributed.process - INFO - reaping stray process <SpawnProcess name='Dask Worker process (from Nanny)' pid=1190101 parent=1190068 started daemon>
2023-04-04 04:14:25,591 - distributed.process - INFO - reaping stray process <SpawnProcess name='Dask Worker process (from Nanny)' pid=1190098 parent=1190068 started daemon>
2023-04-04 04:14:25,845 - distributed.process - WARNING - [<AsyncProcess Dask Worker process (from Nanny)>] process 1190101 exit status was already read will report exitcode 255
2023-04-04 04:14:26,211 - distributed.process - WARNING - [<AsyncProcess Dask Worker process (from Nanny)>] process 1190098 exit status was already read will report exitcode 255
