RUNNING: "python -m dask_cuda.cli.dask_cuda_worker --rmm-pool-size=28G
             --local-directory=/tmp/
             --scheduler-file=/root/cugraph/python/cugraph-pyg/cugraph_pyg/examples/scheduler.json
             --memory-limit=auto
             --device-memory-limit=auto
            "
2023-04-04 18:02:04,579 - distributed.nanny - INFO -         Start Nanny at: 'tcp://10.120.104.11:33743'
2023-04-04 18:02:04,582 - distributed.nanny - INFO -         Start Nanny at: 'tcp://10.120.104.11:40341'
2023-04-04 18:02:05,737 - distributed.diskutils - INFO - Found stale lock file and directory '/tmp/dask-worker-space/worker-30sqk3kw', purging
2023-04-04 18:02:05,738 - distributed.preloading - INFO - Creating preload: dask_cuda.initialize
2023-04-04 18:02:05,738 - distributed.preloading - INFO - Import preload module: dask_cuda.initialize
2023-04-04 18:02:05,767 - distributed.preloading - INFO - Creating preload: dask_cuda.initialize
2023-04-04 18:02:05,767 - distributed.preloading - INFO - Import preload module: dask_cuda.initialize
2023-04-04 18:02:05,987 - distributed.preloading - INFO - Run preload setup: dask_cuda.initialize
2023-04-04 18:02:06,027 - distributed.preloading - INFO - Run preload setup: dask_cuda.initialize
2023-04-04 18:02:07,091 - distributed.worker - INFO -       Start worker at:  tcp://10.120.104.11:40871
2023-04-04 18:02:07,091 - distributed.worker - INFO -          Listening to:  tcp://10.120.104.11:40871
2023-04-04 18:02:07,091 - distributed.worker - INFO -          dashboard at:        10.120.104.11:44905
2023-04-04 18:02:07,091 - distributed.worker - INFO - Waiting to connect to:   tcp://10.120.104.11:8786
2023-04-04 18:02:07,091 - distributed.worker - INFO - -------------------------------------------------
2023-04-04 18:02:07,091 - distributed.worker - INFO -               Threads:                          1
2023-04-04 18:02:07,091 - distributed.worker - INFO -                Memory:                 755.28 GiB
2023-04-04 18:02:07,091 - distributed.worker - INFO -       Local Directory: /tmp/dask-worker-space/worker-zahza5lg
2023-04-04 18:02:07,092 - distributed.worker - INFO - Starting Worker plugin CPUAffinity-d00eaac6-9d27-4a3f-81cc-172b46bb28e5
2023-04-04 18:02:07,092 - distributed.worker - INFO - Starting Worker plugin RMMSetup-fdb591c8-1875-4414-ab0a-cfde3a72730b
2023-04-04 18:02:07,141 - distributed.worker - INFO -       Start worker at:  tcp://10.120.104.11:37937
2023-04-04 18:02:07,141 - distributed.worker - INFO -          Listening to:  tcp://10.120.104.11:37937
2023-04-04 18:02:07,142 - distributed.worker - INFO -          dashboard at:        10.120.104.11:42789
2023-04-04 18:02:07,142 - distributed.worker - INFO - Waiting to connect to:   tcp://10.120.104.11:8786
2023-04-04 18:02:07,142 - distributed.worker - INFO - -------------------------------------------------
2023-04-04 18:02:07,142 - distributed.worker - INFO -               Threads:                          1
2023-04-04 18:02:07,142 - distributed.worker - INFO -                Memory:                 755.28 GiB
2023-04-04 18:02:07,142 - distributed.worker - INFO -       Local Directory: /tmp/dask-worker-space/worker-e5rcr8jl
2023-04-04 18:02:07,142 - distributed.worker - INFO - Starting Worker plugin CPUAffinity-6b03a2fa-c5a0-4de0-bf62-95b637f69df2
2023-04-04 18:02:07,143 - distributed.worker - INFO - Starting Worker plugin PreImport-a0743ce9-097f-4a8f-b619-e0391aa8229d
2023-04-04 18:02:07,143 - distributed.worker - INFO - Starting Worker plugin RMMSetup-ce46b493-c147-4f74-8e71-86e628eb8f74
2023-04-04 18:02:07,231 - distributed.worker - INFO - Starting Worker plugin PreImport-3be53668-1d3e-44ec-94e3-dfc977e98174
2023-04-04 18:02:07,232 - distributed.worker - INFO - -------------------------------------------------
2023-04-04 18:02:07,242 - distributed.worker - INFO -         Registered to:   tcp://10.120.104.11:8786
2023-04-04 18:02:07,242 - distributed.worker - INFO - -------------------------------------------------
2023-04-04 18:02:07,244 - distributed.core - INFO - Starting established connection to tcp://10.120.104.11:8786
2023-04-04 18:02:07,285 - distributed.worker - INFO - -------------------------------------------------
2023-04-04 18:02:07,295 - distributed.worker - INFO -         Registered to:   tcp://10.120.104.11:8786
2023-04-04 18:02:07,295 - distributed.worker - INFO - -------------------------------------------------
2023-04-04 18:02:07,297 - distributed.core - INFO - Starting established connection to tcp://10.120.104.11:8786
2023-04-04 18:02:22,925 - distributed.worker - INFO - Run out-of-band function '_func_ucp_listener_port'
2023-04-04 18:02:22,928 - distributed.worker - INFO - Run out-of-band function '_func_ucp_listener_port'
2023-04-04 18:02:23,743 - distributed.worker - INFO - Run out-of-band function '_func_init_all'
2023-04-04 18:02:23,743 - distributed.worker - INFO - Run out-of-band function '_func_init_all'
2023-04-04 18:02:24,389 - distributed.worker - INFO - Run out-of-band function '_func_ucp_listener_port'
2023-04-04 18:02:24,390 - distributed.worker - INFO - Run out-of-band function '_func_ucp_listener_port'
2023-04-04 18:02:24,396 - distributed.worker - INFO - Run out-of-band function '_func_init_all'
2023-04-04 18:02:24,407 - distributed.worker - INFO - Run out-of-band function '_func_init_all'
2023-04-04 18:02:32,891 - distributed.worker - INFO - Run out-of-band function '_subcomm_init'
2023-04-04 18:02:32,892 - distributed.worker - INFO - Run out-of-band function '_subcomm_init'
2023-04-04 18:02:39,801 - distributed.core - INFO - Event loop was unresponsive in Worker for 15.19s.  This is often caused by long-running GIL-holding functions or moving large chunks of data. This can cause timeouts and instability.
2023-04-04 18:02:39,804 - distributed.core - INFO - Event loop was unresponsive in Worker for 15.19s.  This is often caused by long-running GIL-holding functions or moving large chunks of data. This can cause timeouts and instability.
2023-04-04 18:02:39,812 - distributed.worker - INFO - Run out-of-band function '_subcomm_init'
2023-04-04 18:02:39,813 - distributed.worker - INFO - Run out-of-band function '_subcomm_init'
2023-04-04 18:02:49,896 - distributed.worker - INFO - Run out-of-band function '_func_ucp_listener_port'
2023-04-04 18:02:49,898 - distributed.worker - INFO - Run out-of-band function '_func_ucp_listener_port'
2023-04-04 18:02:50,363 - distributed.worker - INFO - Run out-of-band function '_func_ucp_listener_port'
2023-04-04 18:02:50,363 - distributed.worker - INFO - Run out-of-band function '_func_ucp_listener_port'
2023-04-04 18:02:52,643 - distributed.worker - INFO - Run out-of-band function '_func_ucp_listener_port'
2023-04-04 18:02:52,644 - distributed.worker - INFO - Run out-of-band function '_func_ucp_listener_port'
2023-04-04 18:02:54,701 - distributed.worker - INFO - Run out-of-band function '_func_ucp_listener_port'
2023-04-04 18:02:54,702 - distributed.worker - INFO - Run out-of-band function '_func_ucp_listener_port'
2023-04-04 18:02:54,912 - distributed.worker - INFO - Run out-of-band function '_func_ucp_listener_port'
2023-04-04 18:02:54,912 - distributed.worker - INFO - Run out-of-band function '_func_ucp_listener_port'
2023-04-04 18:02:58,588 - distributed.worker - INFO - Run out-of-band function '_func_ucp_listener_port'
2023-04-04 18:02:58,588 - distributed.worker - INFO - Run out-of-band function '_func_ucp_listener_port'
2023-04-04 18:02:58,793 - distributed.worker - INFO - Run out-of-band function '_func_ucp_listener_port'
2023-04-04 18:02:58,793 - distributed.worker - INFO - Run out-of-band function '_func_ucp_listener_port'
2023-04-04 18:03:02,260 - distributed.worker - INFO - Run out-of-band function '_func_ucp_listener_port'
2023-04-04 18:03:02,260 - distributed.worker - INFO - Run out-of-band function '_func_ucp_listener_port'
2023-04-04 18:03:02,467 - distributed.worker - INFO - Run out-of-band function '_func_ucp_listener_port'
2023-04-04 18:03:02,468 - distributed.worker - INFO - Run out-of-band function '_func_ucp_listener_port'
2023-04-04 18:03:05,968 - distributed.worker - INFO - Run out-of-band function '_func_ucp_listener_port'
2023-04-04 18:03:05,969 - distributed.worker - INFO - Run out-of-band function '_func_ucp_listener_port'
2023-04-04 18:03:06,173 - distributed.worker - INFO - Run out-of-band function '_func_ucp_listener_port'
2023-04-04 18:03:06,174 - distributed.worker - INFO - Run out-of-band function '_func_ucp_listener_port'
2023-04-04 18:03:09,685 - distributed.worker - INFO - Run out-of-band function '_func_ucp_listener_port'
2023-04-04 18:03:09,685 - distributed.worker - INFO - Run out-of-band function '_func_ucp_listener_port'
2023-04-04 18:03:09,896 - distributed.worker - INFO - Run out-of-band function '_func_ucp_listener_port'
2023-04-04 18:03:09,896 - distributed.worker - INFO - Run out-of-band function '_func_ucp_listener_port'
2023-04-04 18:03:13,423 - distributed.worker - INFO - Run out-of-band function '_func_ucp_listener_port'
2023-04-04 18:03:13,423 - distributed.worker - INFO - Run out-of-band function '_func_ucp_listener_port'
2023-04-04 18:03:13,480 - distributed.worker - INFO - Run out-of-band function '_func_ucp_listener_port'
2023-04-04 18:03:13,480 - distributed.worker - INFO - Run out-of-band function '_func_ucp_listener_port'
2023-04-04 18:03:16,316 - distributed.worker - INFO - Run out-of-band function '_func_ucp_listener_port'
2023-04-04 18:03:16,317 - distributed.worker - INFO - Run out-of-band function '_func_ucp_listener_port'
2023-04-04 18:03:18,319 - distributed.worker - INFO - Run out-of-band function '_func_ucp_listener_port'
2023-04-04 18:03:18,320 - distributed.worker - INFO - Run out-of-band function '_func_ucp_listener_port'
2023-04-04 18:09:40,806 - distributed.worker - INFO - Stopping worker at tcp://10.120.104.11:37937. Reason: worker-handle-scheduler-connection-broken
2023-04-04 18:09:40,807 - distributed.worker - INFO - Stopping worker at tcp://10.120.104.11:40871. Reason: worker-close
2023-04-04 18:09:40,808 - distributed.batched - INFO - Batched Comm Closed <TCP (closed) Worker->Scheduler local=tcp://10.120.104.11:45598 remote=tcp://10.120.104.11:8786>
Traceback (most recent call last):
  File "/opt/conda/envs/rapids/lib/python3.10/asyncio/runners.py", line 44, in run
    return loop.run_until_complete(main)
  File "/opt/conda/envs/rapids/lib/python3.10/asyncio/base_events.py", line 636, in run_until_complete
    self.run_forever()
  File "/opt/conda/envs/rapids/lib/python3.10/asyncio/base_events.py", line 603, in run_forever
    self._run_once()
  File "/opt/conda/envs/rapids/lib/python3.10/asyncio/base_events.py", line 1868, in _run_once
    event_list = self._selector.select(timeout)
  File "/opt/conda/envs/rapids/lib/python3.10/selectors.py", line 469, in select
    fd_event_list = self._selector.poll(timeout, max_ev)
KeyboardInterrupt

During handling of the above exception, another exception occurred:

Traceback (most recent call last):
  File "/opt/conda/envs/rapids/lib/python3.10/site-packages/distributed/batched.py", line 115, in _background_send
    nbytes = yield coro
  File "/opt/conda/envs/rapids/lib/python3.10/site-packages/tornado/gen.py", line 769, in run
    value = future.result()
  File "/opt/conda/envs/rapids/lib/python3.10/site-packages/distributed/comm/tcp.py", line 269, in write
    raise CommClosedError()
distributed.comm.core.CommClosedError
2023-04-04 18:09:40,810 - distributed.nanny - INFO - Closing Nanny at 'tcp://10.120.104.11:33743'. Reason: nanny-close
2023-04-04 18:09:40,812 - distributed.nanny - INFO - Nanny asking worker to close. Reason: nanny-close
2023-04-04 18:09:40,813 - distributed.nanny - INFO - Closing Nanny at 'tcp://10.120.104.11:40341'. Reason: nanny-close
2023-04-04 18:09:40,814 - distributed.nanny - INFO - Nanny asking worker to close. Reason: nanny-close
2023-04-04 18:09:40,837 - distributed.worker - ERROR - Timed out during handshake while connecting to tcp://10.120.104.11:33743 after 100 s
Traceback (most recent call last):
  File "/opt/conda/envs/rapids/lib/python3.10/asyncio/runners.py", line 44, in run
    return loop.run_until_complete(main)
  File "/opt/conda/envs/rapids/lib/python3.10/asyncio/base_events.py", line 636, in run_until_complete
    self.run_forever()
  File "/opt/conda/envs/rapids/lib/python3.10/asyncio/base_events.py", line 603, in run_forever
    self._run_once()
  File "/opt/conda/envs/rapids/lib/python3.10/asyncio/base_events.py", line 1868, in _run_once
    event_list = self._selector.select(timeout)
  File "/opt/conda/envs/rapids/lib/python3.10/selectors.py", line 469, in select
    fd_event_list = self._selector.poll(timeout, max_ev)
KeyboardInterrupt

During handling of the above exception, another exception occurred:

Traceback (most recent call last):
  File "/opt/conda/envs/rapids/lib/python3.10/site-packages/tornado/iostream.py", line 869, in _read_to_buffer
    bytes_read = self.read_from_fd(buf)
  File "/opt/conda/envs/rapids/lib/python3.10/site-packages/tornado/iostream.py", line 1138, in read_from_fd
    return self.socket.recv_into(buf, len(buf))
ConnectionResetError: [Errno 104] Connection reset by peer

The above exception was the direct cause of the following exception:

Traceback (most recent call last):
  File "/opt/conda/envs/rapids/lib/python3.10/site-packages/distributed/comm/core.py", line 329, in connect
    handshake = await wait_for(comm.read(), time_left())
  File "/opt/conda/envs/rapids/lib/python3.10/site-packages/distributed/utils.py", line 1849, in wait_for
    return await asyncio.wait_for(fut, timeout)
  File "/opt/conda/envs/rapids/lib/python3.10/asyncio/tasks.py", line 445, in wait_for
    return fut.result()
  File "/opt/conda/envs/rapids/lib/python3.10/site-packages/distributed/comm/tcp.py", line 241, in read
    convert_stream_closed_error(self, e)
  File "/opt/conda/envs/rapids/lib/python3.10/site-packages/distributed/comm/tcp.py", line 142, in convert_stream_closed_error
    raise CommClosedError(f"in {obj}: {exc.__class__.__name__}: {exc}") from exc
distributed.comm.core.CommClosedError: in <TCP (closed)  local=tcp://10.120.104.11:60406 remote=tcp://10.120.104.11:33743>: ConnectionResetError: [Errno 104] Connection reset by peer

The above exception was the direct cause of the following exception:

Traceback (most recent call last):
  File "/opt/conda/envs/rapids/lib/python3.10/site-packages/distributed/utils.py", line 752, in wrapper
    return await func(*args, **kwargs)
  File "/opt/conda/envs/rapids/lib/python3.10/site-packages/distributed/worker.py", line 1573, in close
    await r.close_gracefully(reason=reason)
  File "/opt/conda/envs/rapids/lib/python3.10/site-packages/distributed/core.py", line 1262, in send_recv_from_rpc
    comm = await self.pool.connect(self.addr)
  File "/opt/conda/envs/rapids/lib/python3.10/site-packages/distributed/core.py", line 1506, in connect
    return await connect_attempt
  File "/opt/conda/envs/rapids/lib/python3.10/site-packages/distributed/core.py", line 1427, in _connect
    comm = await connect(
  File "/opt/conda/envs/rapids/lib/python3.10/site-packages/distributed/comm/core.py", line 334, in connect
    raise OSError(
OSError: Timed out during handshake while connecting to tcp://10.120.104.11:33743 after 100 s
2023-04-04 18:09:40,840 - distributed.core - ERROR - Timed out during handshake while connecting to tcp://10.120.104.11:40341 after 100 s
Traceback (most recent call last):
  File "/opt/conda/envs/rapids/lib/python3.10/asyncio/runners.py", line 44, in run
    return loop.run_until_complete(main)
  File "/opt/conda/envs/rapids/lib/python3.10/asyncio/base_events.py", line 636, in run_until_complete
    self.run_forever()
  File "/opt/conda/envs/rapids/lib/python3.10/asyncio/base_events.py", line 603, in run_forever
    self._run_once()
  File "/opt/conda/envs/rapids/lib/python3.10/asyncio/base_events.py", line 1868, in _run_once
    event_list = self._selector.select(timeout)
  File "/opt/conda/envs/rapids/lib/python3.10/selectors.py", line 469, in select
    fd_event_list = self._selector.poll(timeout, max_ev)
KeyboardInterrupt

During handling of the above exception, another exception occurred:

Traceback (most recent call last):
  File "/opt/conda/envs/rapids/lib/python3.10/site-packages/tornado/iostream.py", line 869, in _read_to_buffer
    bytes_read = self.read_from_fd(buf)
  File "/opt/conda/envs/rapids/lib/python3.10/site-packages/tornado/iostream.py", line 1138, in read_from_fd
    return self.socket.recv_into(buf, len(buf))
ConnectionResetError: [Errno 104] Connection reset by peer

The above exception was the direct cause of the following exception:

Traceback (most recent call last):
  File "/opt/conda/envs/rapids/lib/python3.10/site-packages/distributed/comm/core.py", line 329, in connect
    handshake = await wait_for(comm.read(), time_left())
  File "/opt/conda/envs/rapids/lib/python3.10/site-packages/distributed/utils.py", line 1849, in wait_for
    return await asyncio.wait_for(fut, timeout)
  File "/opt/conda/envs/rapids/lib/python3.10/asyncio/tasks.py", line 445, in wait_for
    return fut.result()
  File "/opt/conda/envs/rapids/lib/python3.10/site-packages/distributed/comm/tcp.py", line 241, in read
    convert_stream_closed_error(self, e)
  File "/opt/conda/envs/rapids/lib/python3.10/site-packages/distributed/comm/tcp.py", line 142, in convert_stream_closed_error
    raise CommClosedError(f"in {obj}: {exc.__class__.__name__}: {exc}") from exc
distributed.comm.core.CommClosedError: in <TCP (closed)  local=tcp://10.120.104.11:48436 remote=tcp://10.120.104.11:40341>: ConnectionResetError: [Errno 104] Connection reset by peer

The above exception was the direct cause of the following exception:

Traceback (most recent call last):
  File "/opt/conda/envs/rapids/lib/python3.10/site-packages/distributed/utils.py", line 752, in wrapper
    return await func(*args, **kwargs)
  File "/opt/conda/envs/rapids/lib/python3.10/site-packages/distributed/worker.py", line 1573, in close
    await r.close_gracefully(reason=reason)
  File "/opt/conda/envs/rapids/lib/python3.10/site-packages/distributed/core.py", line 1262, in send_recv_from_rpc
    comm = await self.pool.connect(self.addr)
  File "/opt/conda/envs/rapids/lib/python3.10/site-packages/distributed/core.py", line 1506, in connect
    return await connect_attempt
  File "/opt/conda/envs/rapids/lib/python3.10/site-packages/distributed/core.py", line 1427, in _connect
    comm = await connect(
  File "/opt/conda/envs/rapids/lib/python3.10/site-packages/distributed/comm/core.py", line 334, in connect
    raise OSError(
OSError: Timed out during handshake while connecting to tcp://10.120.104.11:40341 after 100 s
2023-04-04 18:09:44,016 - distributed.nanny - WARNING - Worker process still alive after 3.199981689453125 seconds, killing
2023-04-04 18:09:44,017 - distributed.nanny - WARNING - Worker process still alive after 3.1999992370605472 seconds, killing
2023-04-04 18:09:45,068 - distributed.nanny - INFO - Worker process 1479238 was killed by signal 9
2023-04-04 18:09:45,074 - distributed.nanny - ERROR - Error in Nanny killing Worker subprocess
Traceback (most recent call last):
  File "/opt/conda/envs/rapids/lib/python3.10/asyncio/tasks.py", line 456, in wait_for
    return fut.result()
asyncio.exceptions.CancelledError

The above exception was the direct cause of the following exception:

Traceback (most recent call last):
  File "/opt/conda/envs/rapids/lib/python3.10/site-packages/distributed/nanny.py", line 607, in close
    await self.kill(timeout=timeout, reason=reason)
  File "/opt/conda/envs/rapids/lib/python3.10/site-packages/distributed/nanny.py", line 390, in kill
    await self.process.kill(reason=reason, timeout=0.8 * (deadline - time()))
  File "/opt/conda/envs/rapids/lib/python3.10/site-packages/distributed/nanny.py", line 844, in kill
    await process.join(max(0, deadline - time()))
  File "/opt/conda/envs/rapids/lib/python3.10/site-packages/distributed/process.py", line 330, in join
    await wait_for(asyncio.shield(self._exit_future), timeout)
  File "/opt/conda/envs/rapids/lib/python3.10/site-packages/distributed/utils.py", line 1849, in wait_for
    return await asyncio.wait_for(fut, timeout)
  File "/opt/conda/envs/rapids/lib/python3.10/asyncio/tasks.py", line 458, in wait_for
    raise exceptions.TimeoutError() from exc
asyncio.exceptions.TimeoutError
2023-04-04 18:09:45,077 - distributed.process - INFO - reaping stray process <SpawnProcess name='Dask Worker process (from Nanny)' pid=1479235 parent=1479214 started daemon>
2023-04-04 18:09:45,468 - distributed.process - WARNING - [<AsyncProcess Dask Worker process (from Nanny)>] process 1479235 exit status was already read will report exitcode 255
