RUNNING: "python -m dask_cuda.cli.dask_cuda_worker --rmm-pool-size=28G
             --local-directory=/tmp/
             --scheduler-file=/root/cugraph/python/cugraph-pyg/cugraph_pyg/examples/scheduler.json
             --memory-limit=auto
             --device-memory-limit=auto
            "
2023-04-04 15:18:09,317 - distributed.nanny - INFO -         Start Nanny at: 'tcp://10.120.104.11:34329'
2023-04-04 15:18:09,320 - distributed.nanny - INFO -         Start Nanny at: 'tcp://10.120.104.11:45615'
2023-04-04 15:18:10,470 - distributed.diskutils - INFO - Found stale lock file and directory '/tmp/dask-worker-space/worker-jadp605g', purging
2023-04-04 15:18:10,470 - distributed.preloading - INFO - Creating preload: dask_cuda.initialize
2023-04-04 15:18:10,470 - distributed.preloading - INFO - Import preload module: dask_cuda.initialize
2023-04-04 15:18:10,501 - distributed.preloading - INFO - Creating preload: dask_cuda.initialize
2023-04-04 15:18:10,501 - distributed.preloading - INFO - Import preload module: dask_cuda.initialize
2023-04-04 15:18:10,719 - distributed.preloading - INFO - Run preload setup: dask_cuda.initialize
2023-04-04 15:18:10,762 - distributed.preloading - INFO - Run preload setup: dask_cuda.initialize
2023-04-04 15:18:11,837 - distributed.worker - INFO -       Start worker at:  tcp://10.120.104.11:41197
2023-04-04 15:18:11,837 - distributed.worker - INFO -          Listening to:  tcp://10.120.104.11:41197
2023-04-04 15:18:11,837 - distributed.worker - INFO -          dashboard at:        10.120.104.11:33637
2023-04-04 15:18:11,837 - distributed.worker - INFO - Waiting to connect to:   tcp://10.120.104.11:8786
2023-04-04 15:18:11,837 - distributed.worker - INFO - -------------------------------------------------
2023-04-04 15:18:11,837 - distributed.worker - INFO -               Threads:                          1
2023-04-04 15:18:11,837 - distributed.worker - INFO -                Memory:                 755.28 GiB
2023-04-04 15:18:11,837 - distributed.worker - INFO -       Local Directory: /tmp/dask-worker-space/worker-d2em1q5z
2023-04-04 15:18:11,838 - distributed.worker - INFO - Starting Worker plugin RMMSetup-e294ce7d-49d2-4534-ad0f-43cea403599d
2023-04-04 15:18:11,889 - distributed.worker - INFO -       Start worker at:  tcp://10.120.104.11:33677
2023-04-04 15:18:11,889 - distributed.worker - INFO -          Listening to:  tcp://10.120.104.11:33677
2023-04-04 15:18:11,890 - distributed.worker - INFO -          dashboard at:        10.120.104.11:35497
2023-04-04 15:18:11,890 - distributed.worker - INFO - Waiting to connect to:   tcp://10.120.104.11:8786
2023-04-04 15:18:11,890 - distributed.worker - INFO - -------------------------------------------------
2023-04-04 15:18:11,890 - distributed.worker - INFO -               Threads:                          1
2023-04-04 15:18:11,890 - distributed.worker - INFO -                Memory:                 755.28 GiB
2023-04-04 15:18:11,890 - distributed.worker - INFO -       Local Directory: /tmp/dask-worker-space/worker-vxhxjveu
2023-04-04 15:18:11,890 - distributed.worker - INFO - Starting Worker plugin CPUAffinity-901a09f8-e61d-4e13-9ec1-7cc34b9add04
2023-04-04 15:18:11,893 - distributed.worker - INFO - Starting Worker plugin PreImport-f81ec46f-5073-4c71-9207-c05de3536e2b
2023-04-04 15:18:11,894 - distributed.worker - INFO - Starting Worker plugin RMMSetup-ab3c5fa4-9c09-44e5-bb5c-afff45495e1f
2023-04-04 15:18:12,013 - distributed.worker - INFO - Starting Worker plugin PreImport-bcfd82d9-ca6b-4714-bdc9-0d6a046e04c3
2023-04-04 15:18:12,014 - distributed.worker - INFO - Starting Worker plugin CPUAffinity-f6d4e536-4b89-4271-bd6e-e396835a8894
2023-04-04 15:18:12,015 - distributed.worker - INFO - -------------------------------------------------
2023-04-04 15:18:12,028 - distributed.worker - INFO -         Registered to:   tcp://10.120.104.11:8786
2023-04-04 15:18:12,028 - distributed.worker - INFO - -------------------------------------------------
2023-04-04 15:18:12,030 - distributed.core - INFO - Starting established connection to tcp://10.120.104.11:8786
2023-04-04 15:18:12,073 - distributed.worker - INFO - -------------------------------------------------
2023-04-04 15:18:12,083 - distributed.worker - INFO -         Registered to:   tcp://10.120.104.11:8786
2023-04-04 15:18:12,083 - distributed.worker - INFO - -------------------------------------------------
2023-04-04 15:18:12,085 - distributed.core - INFO - Starting established connection to tcp://10.120.104.11:8786
2023-04-04 15:18:27,241 - distributed.worker - INFO - Run out-of-band function '_func_ucp_listener_port'
2023-04-04 15:18:27,244 - distributed.worker - INFO - Run out-of-band function '_func_ucp_listener_port'
2023-04-04 15:18:28,063 - distributed.worker - INFO - Run out-of-band function '_func_init_all'
2023-04-04 15:18:28,063 - distributed.worker - INFO - Run out-of-band function '_func_init_all'
2023-04-04 15:18:28,685 - distributed.worker - INFO - Run out-of-band function '_func_ucp_listener_port'
2023-04-04 15:18:28,692 - distributed.worker - INFO - Run out-of-band function '_func_ucp_listener_port'
2023-04-04 15:18:28,697 - distributed.worker - INFO - Run out-of-band function '_func_init_all'
2023-04-04 15:18:28,700 - distributed.worker - INFO - Run out-of-band function '_func_init_all'
2023-04-04 15:18:37,320 - distributed.worker - INFO - Run out-of-band function '_subcomm_init'
2023-04-04 15:18:37,411 - distributed.worker - INFO - Run out-of-band function '_subcomm_init'
2023-04-04 15:18:44,402 - distributed.core - INFO - Event loop was unresponsive in Worker for 15.49s.  This is often caused by long-running GIL-holding functions or moving large chunks of data. This can cause timeouts and instability.
2023-04-04 15:18:44,402 - distributed.core - INFO - Event loop was unresponsive in Worker for 15.50s.  This is often caused by long-running GIL-holding functions or moving large chunks of data. This can cause timeouts and instability.
2023-04-04 15:18:44,408 - distributed.worker - INFO - Run out-of-band function '_subcomm_init'
2023-04-04 15:18:44,408 - distributed.worker - INFO - Run out-of-band function '_subcomm_init'
2023-04-04 15:18:54,207 - distributed.worker - INFO - Run out-of-band function '_func_ucp_listener_port'
2023-04-04 15:18:54,210 - distributed.worker - INFO - Run out-of-band function '_func_ucp_listener_port'
2023-04-04 15:20:44,257 - distributed.worker - INFO - Stopping worker at tcp://10.120.104.11:33677. Reason: worker-handle-scheduler-connection-broken
2023-04-04 15:20:44,257 - distributed.worker - INFO - Stopping worker at tcp://10.120.104.11:41197. Reason: worker-handle-scheduler-connection-broken
2023-04-04 15:20:44,257 - distributed.nanny - INFO - Closing Nanny at 'tcp://10.120.104.11:34329'. Reason: nanny-close
2023-04-04 15:20:44,257 - distributed.nanny - INFO - Nanny asking worker to close. Reason: nanny-close
2023-04-04 15:20:44,258 - distributed.nanny - INFO - Closing Nanny at 'tcp://10.120.104.11:45615'. Reason: nanny-close
2023-04-04 15:20:44,259 - distributed.nanny - INFO - Nanny asking worker to close. Reason: nanny-close
2023-04-04 15:20:44,281 - distributed.worker - ERROR - Timed out during handshake while connecting to tcp://10.120.104.11:45615 after 100 s
Traceback (most recent call last):
  File "/opt/conda/envs/rapids/lib/python3.10/asyncio/runners.py", line 44, in run
    return loop.run_until_complete(main)
  File "/opt/conda/envs/rapids/lib/python3.10/asyncio/base_events.py", line 636, in run_until_complete
    self.run_forever()
  File "/opt/conda/envs/rapids/lib/python3.10/asyncio/base_events.py", line 603, in run_forever
    self._run_once()
  File "/opt/conda/envs/rapids/lib/python3.10/asyncio/base_events.py", line 1868, in _run_once
    event_list = self._selector.select(timeout)
  File "/opt/conda/envs/rapids/lib/python3.10/selectors.py", line 469, in select
    fd_event_list = self._selector.poll(timeout, max_ev)
KeyboardInterrupt

During handling of the above exception, another exception occurred:

Traceback (most recent call last):
  File "/opt/conda/envs/rapids/lib/python3.10/site-packages/tornado/iostream.py", line 869, in _read_to_buffer
    bytes_read = self.read_from_fd(buf)
  File "/opt/conda/envs/rapids/lib/python3.10/site-packages/tornado/iostream.py", line 1138, in read_from_fd
    return self.socket.recv_into(buf, len(buf))
ConnectionResetError: [Errno 104] Connection reset by peer

The above exception was the direct cause of the following exception:

Traceback (most recent call last):
  File "/opt/conda/envs/rapids/lib/python3.10/site-packages/distributed/comm/core.py", line 329, in connect
    handshake = await wait_for(comm.read(), time_left())
  File "/opt/conda/envs/rapids/lib/python3.10/site-packages/distributed/utils.py", line 1849, in wait_for
    return await asyncio.wait_for(fut, timeout)
  File "/opt/conda/envs/rapids/lib/python3.10/asyncio/tasks.py", line 445, in wait_for
    return fut.result()
  File "/opt/conda/envs/rapids/lib/python3.10/site-packages/distributed/comm/tcp.py", line 241, in read
    convert_stream_closed_error(self, e)
  File "/opt/conda/envs/rapids/lib/python3.10/site-packages/distributed/comm/tcp.py", line 142, in convert_stream_closed_error
    raise CommClosedError(f"in {obj}: {exc.__class__.__name__}: {exc}") from exc
distributed.comm.core.CommClosedError: in <TCP (closed)  local=tcp://10.120.104.11:36836 remote=tcp://10.120.104.11:45615>: ConnectionResetError: [Errno 104] Connection reset by peer

The above exception was the direct cause of the following exception:

Traceback (most recent call last):
  File "/opt/conda/envs/rapids/lib/python3.10/site-packages/distributed/utils.py", line 752, in wrapper
    return await func(*args, **kwargs)
  File "/opt/conda/envs/rapids/lib/python3.10/site-packages/distributed/worker.py", line 1573, in close
    await r.close_gracefully(reason=reason)
  File "/opt/conda/envs/rapids/lib/python3.10/site-packages/distributed/core.py", line 1262, in send_recv_from_rpc
    comm = await self.pool.connect(self.addr)
  File "/opt/conda/envs/rapids/lib/python3.10/site-packages/distributed/core.py", line 1506, in connect
    return await connect_attempt
  File "/opt/conda/envs/rapids/lib/python3.10/site-packages/distributed/core.py", line 1427, in _connect
    comm = await connect(
  File "/opt/conda/envs/rapids/lib/python3.10/site-packages/distributed/comm/core.py", line 334, in connect
    raise OSError(
OSError: Timed out during handshake while connecting to tcp://10.120.104.11:45615 after 100 s
2023-04-04 15:20:47,460 - distributed.nanny - WARNING - Worker process still alive after 3.199996490478516 seconds, killing
2023-04-04 15:20:47,460 - distributed.nanny - WARNING - Worker process still alive after 3.199999389648438 seconds, killing
2023-04-04 15:20:48,258 - distributed.nanny - ERROR - Error in Nanny killing Worker subprocess
Traceback (most recent call last):
  File "/opt/conda/envs/rapids/lib/python3.10/asyncio/tasks.py", line 456, in wait_for
    return fut.result()
asyncio.exceptions.CancelledError

The above exception was the direct cause of the following exception:

Traceback (most recent call last):
  File "/opt/conda/envs/rapids/lib/python3.10/site-packages/distributed/nanny.py", line 607, in close
    await self.kill(timeout=timeout, reason=reason)
  File "/opt/conda/envs/rapids/lib/python3.10/site-packages/distributed/nanny.py", line 390, in kill
    await self.process.kill(reason=reason, timeout=0.8 * (deadline - time()))
  File "/opt/conda/envs/rapids/lib/python3.10/site-packages/distributed/nanny.py", line 844, in kill
    await process.join(max(0, deadline - time()))
  File "/opt/conda/envs/rapids/lib/python3.10/site-packages/distributed/process.py", line 330, in join
    await wait_for(asyncio.shield(self._exit_future), timeout)
  File "/opt/conda/envs/rapids/lib/python3.10/site-packages/distributed/utils.py", line 1849, in wait_for
    return await asyncio.wait_for(fut, timeout)
  File "/opt/conda/envs/rapids/lib/python3.10/asyncio/tasks.py", line 458, in wait_for
    raise exceptions.TimeoutError() from exc
asyncio.exceptions.TimeoutError
2023-04-04 15:20:48,259 - distributed.nanny - ERROR - Error in Nanny killing Worker subprocess
Traceback (most recent call last):
  File "/opt/conda/envs/rapids/lib/python3.10/asyncio/tasks.py", line 456, in wait_for
    return fut.result()
asyncio.exceptions.CancelledError

The above exception was the direct cause of the following exception:

Traceback (most recent call last):
  File "/opt/conda/envs/rapids/lib/python3.10/site-packages/distributed/nanny.py", line 607, in close
    await self.kill(timeout=timeout, reason=reason)
  File "/opt/conda/envs/rapids/lib/python3.10/site-packages/distributed/nanny.py", line 390, in kill
    await self.process.kill(reason=reason, timeout=0.8 * (deadline - time()))
  File "/opt/conda/envs/rapids/lib/python3.10/site-packages/distributed/nanny.py", line 844, in kill
    await process.join(max(0, deadline - time()))
  File "/opt/conda/envs/rapids/lib/python3.10/site-packages/distributed/process.py", line 330, in join
    await wait_for(asyncio.shield(self._exit_future), timeout)
  File "/opt/conda/envs/rapids/lib/python3.10/site-packages/distributed/utils.py", line 1849, in wait_for
    return await asyncio.wait_for(fut, timeout)
  File "/opt/conda/envs/rapids/lib/python3.10/asyncio/tasks.py", line 458, in wait_for
    raise exceptions.TimeoutError() from exc
asyncio.exceptions.TimeoutError
2023-04-04 15:20:48,260 - distributed.process - INFO - reaping stray process <SpawnProcess name='Dask Worker process (from Nanny)' pid=1350973 parent=1350939 started daemon>
2023-04-04 15:20:48,260 - distributed.process - INFO - reaping stray process <SpawnProcess name='Dask Worker process (from Nanny)' pid=1350970 parent=1350939 started daemon>
2023-04-04 15:20:48,396 - distributed.process - WARNING - [<AsyncProcess Dask Worker process (from Nanny)>] process 1350973 exit status was already read will report exitcode 255
