RUNNING: "python -m dask_cuda.cli.dask_cuda_worker --rmm-pool-size=28G
             --local-directory=/tmp/
             --scheduler-file=/root/cugraph/python/cugraph-pyg/cugraph_pyg/examples/scheduler.json
             --memory-limit=auto
             --device-memory-limit=auto
            "
2023-04-04 04:14:53,765 - distributed.nanny - INFO -         Start Nanny at: 'tcp://10.120.104.11:32899'
2023-04-04 04:14:53,767 - distributed.nanny - INFO -         Start Nanny at: 'tcp://10.120.104.11:45477'
2023-04-04 04:14:54,925 - distributed.diskutils - INFO - Found stale lock file and directory '/tmp/dask-worker-space/worker-l8f7ygbl', purging
2023-04-04 04:14:54,925 - distributed.diskutils - INFO - Found stale lock file and directory '/tmp/dask-worker-space/worker-silao_99', purging
2023-04-04 04:14:54,926 - distributed.preloading - INFO - Creating preload: dask_cuda.initialize
2023-04-04 04:14:54,926 - distributed.preloading - INFO - Creating preload: dask_cuda.initialize
2023-04-04 04:14:54,926 - distributed.preloading - INFO - Import preload module: dask_cuda.initialize
2023-04-04 04:14:54,926 - distributed.preloading - INFO - Import preload module: dask_cuda.initialize
2023-04-04 04:14:55,218 - distributed.preloading - INFO - Run preload setup: dask_cuda.initialize
2023-04-04 04:14:55,239 - distributed.preloading - INFO - Run preload setup: dask_cuda.initialize
2023-04-04 04:14:56,456 - distributed.worker - INFO -       Start worker at:  tcp://10.120.104.11:38041
2023-04-04 04:14:56,456 - distributed.worker - INFO -          Listening to:  tcp://10.120.104.11:38041
2023-04-04 04:14:56,456 - distributed.worker - INFO -          dashboard at:        10.120.104.11:36469
2023-04-04 04:14:56,456 - distributed.worker - INFO - Waiting to connect to:   tcp://10.120.104.11:8786
2023-04-04 04:14:56,456 - distributed.worker - INFO - -------------------------------------------------
2023-04-04 04:14:56,456 - distributed.worker - INFO -               Threads:                          1
2023-04-04 04:14:56,456 - distributed.worker - INFO -                Memory:                 755.28 GiB
2023-04-04 04:14:56,456 - distributed.worker - INFO -       Local Directory: /tmp/dask-worker-space/worker-js_dja94
2023-04-04 04:14:56,457 - distributed.worker - INFO - Starting Worker plugin CPUAffinity-0f3561e7-70a9-4e70-b93c-7d2a09b36b76
2023-04-04 04:14:56,457 - distributed.worker - INFO - Starting Worker plugin PreImport-1cefaae2-9fff-45ef-ba54-0d41161dd824
2023-04-04 04:14:56,457 - distributed.worker - INFO - Starting Worker plugin RMMSetup-02467cc9-2ede-41ab-be82-a65679111f1c
2023-04-04 04:14:56,478 - distributed.worker - INFO -       Start worker at:  tcp://10.120.104.11:36263
2023-04-04 04:14:56,478 - distributed.worker - INFO -          Listening to:  tcp://10.120.104.11:36263
2023-04-04 04:14:56,478 - distributed.worker - INFO -          dashboard at:        10.120.104.11:35239
2023-04-04 04:14:56,478 - distributed.worker - INFO - Waiting to connect to:   tcp://10.120.104.11:8786
2023-04-04 04:14:56,478 - distributed.worker - INFO - -------------------------------------------------
2023-04-04 04:14:56,478 - distributed.worker - INFO -               Threads:                          1
2023-04-04 04:14:56,478 - distributed.worker - INFO -                Memory:                 755.28 GiB
2023-04-04 04:14:56,478 - distributed.worker - INFO -       Local Directory: /tmp/dask-worker-space/worker-2a6ydpgu
2023-04-04 04:14:56,478 - distributed.worker - INFO - Starting Worker plugin RMMSetup-b92dd732-10e4-4f20-9cf3-9b2018bdb60e
2023-04-04 04:14:56,599 - distributed.worker - INFO - -------------------------------------------------
2023-04-04 04:14:56,611 - distributed.worker - INFO -         Registered to:   tcp://10.120.104.11:8786
2023-04-04 04:14:56,612 - distributed.worker - INFO - -------------------------------------------------
2023-04-04 04:14:56,614 - distributed.core - INFO - Starting established connection to tcp://10.120.104.11:8786
2023-04-04 04:14:56,645 - distributed.worker - INFO - Starting Worker plugin PreImport-c5e4b408-7d5c-4550-a4f8-814e9962e1dd
2023-04-04 04:14:56,645 - distributed.worker - INFO - Starting Worker plugin CPUAffinity-baa853f6-6602-44a5-8bc5-7ed007984116
2023-04-04 04:14:56,646 - distributed.worker - INFO - -------------------------------------------------
2023-04-04 04:14:56,655 - distributed.worker - INFO -         Registered to:   tcp://10.120.104.11:8786
2023-04-04 04:14:56,655 - distributed.worker - INFO - -------------------------------------------------
2023-04-04 04:14:56,656 - distributed.core - INFO - Starting established connection to tcp://10.120.104.11:8786
2023-04-04 04:15:16,133 - distributed.worker - INFO - Run out-of-band function '_func_ucp_listener_port'
2023-04-04 04:15:16,135 - distributed.worker - INFO - Run out-of-band function '_func_ucp_listener_port'
2023-04-04 04:15:16,955 - distributed.worker - INFO - Run out-of-band function '_func_init_all'
2023-04-04 04:15:16,955 - distributed.worker - INFO - Run out-of-band function '_func_init_all'
2023-04-04 04:15:17,589 - distributed.worker - INFO - Run out-of-band function '_func_ucp_listener_port'
2023-04-04 04:15:17,605 - distributed.worker - INFO - Run out-of-band function '_func_ucp_listener_port'
2023-04-04 04:15:17,614 - distributed.worker - INFO - Run out-of-band function '_func_init_all'
2023-04-04 04:15:17,622 - distributed.worker - INFO - Run out-of-band function '_func_init_all'
2023-04-04 04:15:25,680 - distributed.worker - INFO - Run out-of-band function '_subcomm_init'
2023-04-04 04:15:25,960 - distributed.worker - INFO - Run out-of-band function '_subcomm_init'
2023-04-04 04:15:32,548 - distributed.core - INFO - Event loop was unresponsive in Worker for 14.73s.  This is often caused by long-running GIL-holding functions or moving large chunks of data. This can cause timeouts and instability.
2023-04-04 04:15:32,552 - distributed.core - INFO - Event loop was unresponsive in Worker for 14.74s.  This is often caused by long-running GIL-holding functions or moving large chunks of data. This can cause timeouts and instability.
2023-04-04 04:15:32,561 - distributed.worker - INFO - Run out-of-band function '_subcomm_init'
2023-04-04 04:15:32,561 - distributed.worker - INFO - Run out-of-band function '_subcomm_init'
2023-04-04 04:15:42,482 - distributed.worker - INFO - Run out-of-band function '_func_ucp_listener_port'
2023-04-04 04:15:42,483 - distributed.worker - INFO - Run out-of-band function '_func_ucp_listener_port'
2023-04-04 04:17:34,707 - distributed.nanny - INFO - Closing Nanny at 'tcp://10.120.104.11:32899'. Reason: nanny-close
2023-04-04 04:17:34,707 - distributed.worker - INFO - Stopping worker at tcp://10.120.104.11:38041. Reason: worker-handle-scheduler-connection-broken
2023-04-04 04:17:34,707 - distributed.worker - INFO - Stopping worker at tcp://10.120.104.11:36263. Reason: worker-handle-scheduler-connection-broken
2023-04-04 04:17:34,708 - distributed.nanny - INFO - Nanny asking worker to close. Reason: nanny-close
2023-04-04 04:17:34,708 - distributed.nanny - INFO - Closing Nanny at 'tcp://10.120.104.11:45477'. Reason: nanny-close
2023-04-04 04:17:34,709 - distributed.nanny - INFO - Nanny asking worker to close. Reason: nanny-close
2023-04-04 04:17:34,736 - distributed.worker - ERROR - Timed out during handshake while connecting to tcp://10.120.104.11:45477 after 100 s
Traceback (most recent call last):
  File "/opt/conda/envs/rapids/lib/python3.10/asyncio/runners.py", line 44, in run
    return loop.run_until_complete(main)
  File "/opt/conda/envs/rapids/lib/python3.10/asyncio/base_events.py", line 636, in run_until_complete
    self.run_forever()
  File "/opt/conda/envs/rapids/lib/python3.10/asyncio/base_events.py", line 603, in run_forever
    self._run_once()
  File "/opt/conda/envs/rapids/lib/python3.10/asyncio/base_events.py", line 1868, in _run_once
    event_list = self._selector.select(timeout)
  File "/opt/conda/envs/rapids/lib/python3.10/selectors.py", line 469, in select
    fd_event_list = self._selector.poll(timeout, max_ev)
KeyboardInterrupt

During handling of the above exception, another exception occurred:

Traceback (most recent call last):
  File "/opt/conda/envs/rapids/lib/python3.10/site-packages/tornado/iostream.py", line 869, in _read_to_buffer
    bytes_read = self.read_from_fd(buf)
  File "/opt/conda/envs/rapids/lib/python3.10/site-packages/tornado/iostream.py", line 1138, in read_from_fd
    return self.socket.recv_into(buf, len(buf))
ConnectionResetError: [Errno 104] Connection reset by peer

The above exception was the direct cause of the following exception:

Traceback (most recent call last):
  File "/opt/conda/envs/rapids/lib/python3.10/site-packages/distributed/comm/core.py", line 329, in connect
    handshake = await wait_for(comm.read(), time_left())
  File "/opt/conda/envs/rapids/lib/python3.10/site-packages/distributed/utils.py", line 1849, in wait_for
    return await asyncio.wait_for(fut, timeout)
  File "/opt/conda/envs/rapids/lib/python3.10/asyncio/tasks.py", line 445, in wait_for
    return fut.result()
  File "/opt/conda/envs/rapids/lib/python3.10/site-packages/distributed/comm/tcp.py", line 241, in read
    convert_stream_closed_error(self, e)
  File "/opt/conda/envs/rapids/lib/python3.10/site-packages/distributed/comm/tcp.py", line 142, in convert_stream_closed_error
    raise CommClosedError(f"in {obj}: {exc.__class__.__name__}: {exc}") from exc
distributed.comm.core.CommClosedError: in <TCP (closed)  local=tcp://10.120.104.11:39354 remote=tcp://10.120.104.11:45477>: ConnectionResetError: [Errno 104] Connection reset by peer

The above exception was the direct cause of the following exception:

Traceback (most recent call last):
  File "/opt/conda/envs/rapids/lib/python3.10/site-packages/distributed/utils.py", line 752, in wrapper
    return await func(*args, **kwargs)
  File "/opt/conda/envs/rapids/lib/python3.10/site-packages/distributed/worker.py", line 1573, in close
    await r.close_gracefully(reason=reason)
  File "/opt/conda/envs/rapids/lib/python3.10/site-packages/distributed/core.py", line 1262, in send_recv_from_rpc
    comm = await self.pool.connect(self.addr)
  File "/opt/conda/envs/rapids/lib/python3.10/site-packages/distributed/core.py", line 1506, in connect
    return await connect_attempt
  File "/opt/conda/envs/rapids/lib/python3.10/site-packages/distributed/core.py", line 1427, in _connect
    comm = await connect(
  File "/opt/conda/envs/rapids/lib/python3.10/site-packages/distributed/comm/core.py", line 334, in connect
    raise OSError(
OSError: Timed out during handshake while connecting to tcp://10.120.104.11:45477 after 100 s
2023-04-04 04:17:37,912 - distributed.nanny - WARNING - Worker process still alive after 3.1999929809570316 seconds, killing
2023-04-04 04:17:37,912 - distributed.nanny - WARNING - Worker process still alive after 3.1999992370605472 seconds, killing
2023-04-04 04:17:38,955 - distributed.nanny - INFO - Worker process 1194169 was killed by signal 9
2023-04-04 04:17:38,957 - distributed.nanny - ERROR - Error in Nanny killing Worker subprocess
Traceback (most recent call last):
  File "/opt/conda/envs/rapids/lib/python3.10/asyncio/tasks.py", line 456, in wait_for
    return fut.result()
asyncio.exceptions.CancelledError

The above exception was the direct cause of the following exception:

Traceback (most recent call last):
  File "/opt/conda/envs/rapids/lib/python3.10/site-packages/distributed/nanny.py", line 607, in close
    await self.kill(timeout=timeout, reason=reason)
  File "/opt/conda/envs/rapids/lib/python3.10/site-packages/distributed/nanny.py", line 390, in kill
    await self.process.kill(reason=reason, timeout=0.8 * (deadline - time()))
  File "/opt/conda/envs/rapids/lib/python3.10/site-packages/distributed/nanny.py", line 844, in kill
    await process.join(max(0, deadline - time()))
  File "/opt/conda/envs/rapids/lib/python3.10/site-packages/distributed/process.py", line 330, in join
    await wait_for(asyncio.shield(self._exit_future), timeout)
  File "/opt/conda/envs/rapids/lib/python3.10/site-packages/distributed/utils.py", line 1849, in wait_for
    return await asyncio.wait_for(fut, timeout)
  File "/opt/conda/envs/rapids/lib/python3.10/asyncio/tasks.py", line 458, in wait_for
    raise exceptions.TimeoutError() from exc
asyncio.exceptions.TimeoutError
2023-04-04 04:17:38,959 - distributed.process - INFO - reaping stray process <SpawnProcess name='Dask Worker process (from Nanny)' pid=1194166 parent=1194125 started daemon>
2023-04-04 04:17:39,319 - distributed.process - WARNING - [<AsyncProcess Dask Worker process (from Nanny)>] process 1194166 exit status was already read will report exitcode 255
