RUNNING: "python -m dask_cuda.cli.dask_cuda_worker --rmm-pool-size=28G
             --local-directory=/tmp/
             --scheduler-file=/root/cugraph/python/cugraph-pyg/cugraph_pyg/examples/scheduler.json
             --memory-limit=auto
             --device-memory-limit=auto
            "
2023-04-04 03:59:08,183 - distributed.nanny - INFO -         Start Nanny at: 'tcp://10.120.104.11:46449'
2023-04-04 03:59:08,186 - distributed.nanny - INFO -         Start Nanny at: 'tcp://10.120.104.11:36149'
2023-04-04 03:59:09,343 - distributed.diskutils - INFO - Found stale lock file and directory '/tmp/dask-worker-space/worker-c5fvhifb', purging
2023-04-04 03:59:09,343 - distributed.diskutils - INFO - Found stale lock file and directory '/tmp/dask-worker-space/worker-3ziu5m7e', purging
2023-04-04 03:59:09,344 - distributed.preloading - INFO - Creating preload: dask_cuda.initialize
2023-04-04 03:59:09,344 - distributed.preloading - INFO - Import preload module: dask_cuda.initialize
2023-04-04 03:59:09,356 - distributed.preloading - INFO - Creating preload: dask_cuda.initialize
2023-04-04 03:59:09,356 - distributed.preloading - INFO - Import preload module: dask_cuda.initialize
2023-04-04 03:59:09,622 - distributed.preloading - INFO - Run preload setup: dask_cuda.initialize
2023-04-04 03:59:09,650 - distributed.preloading - INFO - Run preload setup: dask_cuda.initialize
2023-04-04 03:59:10,732 - distributed.worker - INFO -       Start worker at:  tcp://10.120.104.11:42873
2023-04-04 03:59:10,732 - distributed.worker - INFO -          Listening to:  tcp://10.120.104.11:42873
2023-04-04 03:59:10,732 - distributed.worker - INFO -          dashboard at:        10.120.104.11:34243
2023-04-04 03:59:10,732 - distributed.worker - INFO - Waiting to connect to:   tcp://10.120.104.11:8786
2023-04-04 03:59:10,733 - distributed.worker - INFO - -------------------------------------------------
2023-04-04 03:59:10,733 - distributed.worker - INFO -               Threads:                          1
2023-04-04 03:59:10,733 - distributed.worker - INFO -                Memory:                 755.28 GiB
2023-04-04 03:59:10,733 - distributed.worker - INFO -       Local Directory: /tmp/dask-worker-space/worker-vmlzs6lz
2023-04-04 03:59:10,733 - distributed.worker - INFO - Starting Worker plugin CPUAffinity-8e8dd911-b0ee-418f-9a88-da8c33325b70
2023-04-04 03:59:10,733 - distributed.worker - INFO - Starting Worker plugin PreImport-b49875ae-b5f2-4ed0-a65e-61d5ccddf6bd
2023-04-04 03:59:10,733 - distributed.worker - INFO - Starting Worker plugin RMMSetup-6d32eb49-a7f9-4e29-8e22-6533da42d255
2023-04-04 03:59:10,753 - distributed.worker - INFO -       Start worker at:  tcp://10.120.104.11:35139
2023-04-04 03:59:10,753 - distributed.worker - INFO -          Listening to:  tcp://10.120.104.11:35139
2023-04-04 03:59:10,753 - distributed.worker - INFO -          dashboard at:        10.120.104.11:36975
2023-04-04 03:59:10,753 - distributed.worker - INFO - Waiting to connect to:   tcp://10.120.104.11:8786
2023-04-04 03:59:10,753 - distributed.worker - INFO - -------------------------------------------------
2023-04-04 03:59:10,753 - distributed.worker - INFO -               Threads:                          1
2023-04-04 03:59:10,753 - distributed.worker - INFO -                Memory:                 755.28 GiB
2023-04-04 03:59:10,753 - distributed.worker - INFO -       Local Directory: /tmp/dask-worker-space/worker-5n7f29p4
2023-04-04 03:59:10,753 - distributed.worker - INFO - Starting Worker plugin RMMSetup-d1344ba7-c7a6-4c97-bc69-ae322a925488
2023-04-04 03:59:10,872 - distributed.worker - INFO - -------------------------------------------------
2023-04-04 03:59:10,882 - distributed.worker - INFO -         Registered to:   tcp://10.120.104.11:8786
2023-04-04 03:59:10,882 - distributed.worker - INFO - -------------------------------------------------
2023-04-04 03:59:10,884 - distributed.core - INFO - Starting established connection to tcp://10.120.104.11:8786
2023-04-04 03:59:10,913 - distributed.worker - INFO - Starting Worker plugin PreImport-6eaaa68b-22f4-4831-a084-cad35d6c13dd
2023-04-04 03:59:10,913 - distributed.worker - INFO - Starting Worker plugin CPUAffinity-5800bacf-0da9-48f2-8e4d-a0624e143efb
2023-04-04 03:59:10,915 - distributed.worker - INFO - -------------------------------------------------
2023-04-04 03:59:10,927 - distributed.worker - INFO -         Registered to:   tcp://10.120.104.11:8786
2023-04-04 03:59:10,927 - distributed.worker - INFO - -------------------------------------------------
2023-04-04 03:59:10,930 - distributed.core - INFO - Starting established connection to tcp://10.120.104.11:8786
2023-04-04 03:59:26,880 - distributed.worker - INFO - Run out-of-band function '_func_ucp_listener_port'
2023-04-04 03:59:26,884 - distributed.worker - INFO - Run out-of-band function '_func_ucp_listener_port'
2023-04-04 03:59:27,711 - distributed.worker - INFO - Run out-of-band function '_func_init_all'
2023-04-04 03:59:27,711 - distributed.worker - INFO - Run out-of-band function '_func_init_all'
2023-04-04 03:59:28,372 - distributed.worker - INFO - Run out-of-band function '_func_ucp_listener_port'
2023-04-04 03:59:28,384 - distributed.worker - INFO - Run out-of-band function '_func_ucp_listener_port'
2023-04-04 03:59:28,389 - distributed.worker - INFO - Run out-of-band function '_func_init_all'
2023-04-04 03:59:28,392 - distributed.worker - INFO - Run out-of-band function '_func_init_all'
2023-04-04 03:59:36,614 - distributed.worker - INFO - Run out-of-band function '_subcomm_init'
2023-04-04 03:59:36,634 - distributed.worker - INFO - Run out-of-band function '_subcomm_init'
2023-04-04 03:59:43,425 - distributed.core - INFO - Event loop was unresponsive in Worker for 14.84s.  This is often caused by long-running GIL-holding functions or moving large chunks of data. This can cause timeouts and instability.
2023-04-04 03:59:43,429 - distributed.core - INFO - Event loop was unresponsive in Worker for 14.84s.  This is often caused by long-running GIL-holding functions or moving large chunks of data. This can cause timeouts and instability.
2023-04-04 03:59:43,438 - distributed.worker - INFO - Run out-of-band function '_subcomm_init'
2023-04-04 03:59:43,438 - distributed.worker - INFO - Run out-of-band function '_subcomm_init'
2023-04-04 03:59:53,408 - distributed.worker - INFO - Run out-of-band function '_func_ucp_listener_port'
2023-04-04 03:59:53,409 - distributed.worker - INFO - Run out-of-band function '_func_ucp_listener_port'
2023-04-04 04:08:05,757 - distributed.nanny - INFO - Closing Nanny at 'tcp://10.120.104.11:46449'. Reason: nanny-close
2023-04-04 04:08:05,757 - distributed.worker - INFO - Stopping worker at tcp://10.120.104.11:35139. Reason: worker-handle-scheduler-connection-broken
2023-04-04 04:08:05,757 - distributed.worker - INFO - Stopping worker at tcp://10.120.104.11:42873. Reason: worker-handle-scheduler-connection-broken
2023-04-04 04:08:05,757 - distributed.nanny - INFO - Nanny asking worker to close. Reason: nanny-close
2023-04-04 04:08:05,758 - distributed.nanny - INFO - Closing Nanny at 'tcp://10.120.104.11:36149'. Reason: nanny-close
2023-04-04 04:08:05,759 - distributed.nanny - INFO - Nanny asking worker to close. Reason: nanny-close
2023-04-04 04:08:05,784 - distributed.worker - ERROR - Timed out during handshake while connecting to tcp://10.120.104.11:36149 after 100 s
Traceback (most recent call last):
  File "/opt/conda/envs/rapids/lib/python3.10/asyncio/runners.py", line 44, in run
    return loop.run_until_complete(main)
  File "/opt/conda/envs/rapids/lib/python3.10/asyncio/base_events.py", line 636, in run_until_complete
    self.run_forever()
  File "/opt/conda/envs/rapids/lib/python3.10/asyncio/base_events.py", line 603, in run_forever
    self._run_once()
  File "/opt/conda/envs/rapids/lib/python3.10/asyncio/base_events.py", line 1868, in _run_once
    event_list = self._selector.select(timeout)
  File "/opt/conda/envs/rapids/lib/python3.10/selectors.py", line 469, in select
    fd_event_list = self._selector.poll(timeout, max_ev)
KeyboardInterrupt

During handling of the above exception, another exception occurred:

Traceback (most recent call last):
  File "/opt/conda/envs/rapids/lib/python3.10/site-packages/tornado/iostream.py", line 869, in _read_to_buffer
    bytes_read = self.read_from_fd(buf)
  File "/opt/conda/envs/rapids/lib/python3.10/site-packages/tornado/iostream.py", line 1138, in read_from_fd
    return self.socket.recv_into(buf, len(buf))
ConnectionResetError: [Errno 104] Connection reset by peer

The above exception was the direct cause of the following exception:

Traceback (most recent call last):
  File "/opt/conda/envs/rapids/lib/python3.10/site-packages/distributed/comm/core.py", line 329, in connect
    handshake = await wait_for(comm.read(), time_left())
  File "/opt/conda/envs/rapids/lib/python3.10/site-packages/distributed/utils.py", line 1849, in wait_for
    return await asyncio.wait_for(fut, timeout)
  File "/opt/conda/envs/rapids/lib/python3.10/asyncio/tasks.py", line 445, in wait_for
    return fut.result()
  File "/opt/conda/envs/rapids/lib/python3.10/site-packages/distributed/comm/tcp.py", line 241, in read
    convert_stream_closed_error(self, e)
  File "/opt/conda/envs/rapids/lib/python3.10/site-packages/distributed/comm/tcp.py", line 142, in convert_stream_closed_error
    raise CommClosedError(f"in {obj}: {exc.__class__.__name__}: {exc}") from exc
distributed.comm.core.CommClosedError: in <TCP (closed)  local=tcp://10.120.104.11:35246 remote=tcp://10.120.104.11:36149>: ConnectionResetError: [Errno 104] Connection reset by peer

The above exception was the direct cause of the following exception:

Traceback (most recent call last):
  File "/opt/conda/envs/rapids/lib/python3.10/site-packages/distributed/utils.py", line 752, in wrapper
    return await func(*args, **kwargs)
  File "/opt/conda/envs/rapids/lib/python3.10/site-packages/distributed/worker.py", line 1573, in close
    await r.close_gracefully(reason=reason)
  File "/opt/conda/envs/rapids/lib/python3.10/site-packages/distributed/core.py", line 1262, in send_recv_from_rpc
    comm = await self.pool.connect(self.addr)
  File "/opt/conda/envs/rapids/lib/python3.10/site-packages/distributed/core.py", line 1506, in connect
    return await connect_attempt
  File "/opt/conda/envs/rapids/lib/python3.10/site-packages/distributed/core.py", line 1427, in _connect
    comm = await connect(
  File "/opt/conda/envs/rapids/lib/python3.10/site-packages/distributed/comm/core.py", line 334, in connect
    raise OSError(
OSError: Timed out during handshake while connecting to tcp://10.120.104.11:36149 after 100 s
2023-04-04 04:08:08,960 - distributed.nanny - WARNING - Worker process still alive after 3.1999961853027346 seconds, killing
2023-04-04 04:08:08,960 - distributed.nanny - WARNING - Worker process still alive after 3.1999995422363288 seconds, killing
2023-04-04 04:08:09,758 - distributed.nanny - ERROR - Error in Nanny killing Worker subprocess
Traceback (most recent call last):
  File "/opt/conda/envs/rapids/lib/python3.10/asyncio/tasks.py", line 456, in wait_for
    return fut.result()
asyncio.exceptions.CancelledError

The above exception was the direct cause of the following exception:

Traceback (most recent call last):
  File "/opt/conda/envs/rapids/lib/python3.10/site-packages/distributed/nanny.py", line 607, in close
    await self.kill(timeout=timeout, reason=reason)
  File "/opt/conda/envs/rapids/lib/python3.10/site-packages/distributed/nanny.py", line 390, in kill
    await self.process.kill(reason=reason, timeout=0.8 * (deadline - time()))
  File "/opt/conda/envs/rapids/lib/python3.10/site-packages/distributed/nanny.py", line 844, in kill
    await process.join(max(0, deadline - time()))
  File "/opt/conda/envs/rapids/lib/python3.10/site-packages/distributed/process.py", line 330, in join
    await wait_for(asyncio.shield(self._exit_future), timeout)
  File "/opt/conda/envs/rapids/lib/python3.10/site-packages/distributed/utils.py", line 1849, in wait_for
    return await asyncio.wait_for(fut, timeout)
  File "/opt/conda/envs/rapids/lib/python3.10/asyncio/tasks.py", line 458, in wait_for
    raise exceptions.TimeoutError() from exc
asyncio.exceptions.TimeoutError
2023-04-04 04:08:09,760 - distributed.nanny - ERROR - Error in Nanny killing Worker subprocess
Traceback (most recent call last):
  File "/opt/conda/envs/rapids/lib/python3.10/asyncio/tasks.py", line 456, in wait_for
    return fut.result()
asyncio.exceptions.CancelledError

The above exception was the direct cause of the following exception:

Traceback (most recent call last):
  File "/opt/conda/envs/rapids/lib/python3.10/site-packages/distributed/nanny.py", line 607, in close
    await self.kill(timeout=timeout, reason=reason)
  File "/opt/conda/envs/rapids/lib/python3.10/site-packages/distributed/nanny.py", line 390, in kill
    await self.process.kill(reason=reason, timeout=0.8 * (deadline - time()))
  File "/opt/conda/envs/rapids/lib/python3.10/site-packages/distributed/nanny.py", line 844, in kill
    await process.join(max(0, deadline - time()))
  File "/opt/conda/envs/rapids/lib/python3.10/site-packages/distributed/process.py", line 330, in join
    await wait_for(asyncio.shield(self._exit_future), timeout)
  File "/opt/conda/envs/rapids/lib/python3.10/site-packages/distributed/utils.py", line 1849, in wait_for
    return await asyncio.wait_for(fut, timeout)
  File "/opt/conda/envs/rapids/lib/python3.10/asyncio/tasks.py", line 458, in wait_for
    raise exceptions.TimeoutError() from exc
asyncio.exceptions.TimeoutError
2023-04-04 04:08:09,761 - distributed.process - INFO - reaping stray process <SpawnProcess name='Dask Worker process (from Nanny)' pid=1180472 parent=1180451 started daemon>
2023-04-04 04:08:09,761 - distributed.process - INFO - reaping stray process <SpawnProcess name='Dask Worker process (from Nanny)' pid=1180469 parent=1180451 started daemon>
