RUNNING: "python -m dask_cuda.cli.dask_cuda_worker --rmm-pool-size=28G
             --local-directory=/tmp/
             --scheduler-file=/root/cugraph/python/cugraph-pyg/cugraph_pyg/examples/scheduler.json
             --memory-limit=auto
             --device-memory-limit=auto
            "
2023-04-04 14:46:22,045 - distributed.nanny - INFO -         Start Nanny at: 'tcp://10.120.104.11:37157'
2023-04-04 14:46:22,048 - distributed.nanny - INFO -         Start Nanny at: 'tcp://10.120.104.11:43933'
2023-04-04 14:46:23,210 - distributed.diskutils - INFO - Found stale lock file and directory '/tmp/dask-worker-space/worker-44e_8q2g', purging
2023-04-04 14:46:23,210 - distributed.diskutils - INFO - Found stale lock file and directory '/tmp/dask-worker-space/worker-uunt_ht8', purging
2023-04-04 14:46:23,211 - distributed.preloading - INFO - Creating preload: dask_cuda.initialize
2023-04-04 14:46:23,211 - distributed.preloading - INFO - Import preload module: dask_cuda.initialize
2023-04-04 14:46:23,235 - distributed.preloading - INFO - Creating preload: dask_cuda.initialize
2023-04-04 14:46:23,235 - distributed.preloading - INFO - Import preload module: dask_cuda.initialize
2023-04-04 14:46:23,464 - distributed.preloading - INFO - Run preload setup: dask_cuda.initialize
2023-04-04 14:46:23,490 - distributed.preloading - INFO - Run preload setup: dask_cuda.initialize
2023-04-04 14:46:24,901 - distributed.worker - INFO -       Start worker at:  tcp://10.120.104.11:41005
2023-04-04 14:46:24,901 - distributed.worker - INFO -          Listening to:  tcp://10.120.104.11:41005
2023-04-04 14:46:24,901 - distributed.worker - INFO -          dashboard at:        10.120.104.11:34105
2023-04-04 14:46:24,901 - distributed.worker - INFO - Waiting to connect to:   tcp://10.120.104.11:8786
2023-04-04 14:46:24,901 - distributed.worker - INFO - -------------------------------------------------
2023-04-04 14:46:24,901 - distributed.worker - INFO -               Threads:                          1
2023-04-04 14:46:24,901 - distributed.worker - INFO -                Memory:                 755.28 GiB
2023-04-04 14:46:24,902 - distributed.worker - INFO -       Local Directory: /tmp/dask-worker-space/worker-8a119409
2023-04-04 14:46:24,902 - distributed.worker - INFO - Starting Worker plugin RMMSetup-a17de226-0ca6-4aa6-ad13-5b1b3a685fcd
2023-04-04 14:46:24,907 - distributed.worker - INFO -       Start worker at:  tcp://10.120.104.11:34103
2023-04-04 14:46:24,907 - distributed.worker - INFO -          Listening to:  tcp://10.120.104.11:34103
2023-04-04 14:46:24,907 - distributed.worker - INFO -          dashboard at:        10.120.104.11:35427
2023-04-04 14:46:24,907 - distributed.worker - INFO - Waiting to connect to:   tcp://10.120.104.11:8786
2023-04-04 14:46:24,907 - distributed.worker - INFO - -------------------------------------------------
2023-04-04 14:46:24,907 - distributed.worker - INFO -               Threads:                          1
2023-04-04 14:46:24,907 - distributed.worker - INFO -                Memory:                 755.28 GiB
2023-04-04 14:46:24,907 - distributed.worker - INFO -       Local Directory: /tmp/dask-worker-space/worker-jdekyku5
2023-04-04 14:46:24,908 - distributed.worker - INFO - Starting Worker plugin PreImport-190746e6-4945-4ca8-bd34-a2fc14b23c83
2023-04-04 14:46:24,908 - distributed.worker - INFO - Starting Worker plugin CPUAffinity-a7e64b53-99f7-428b-ab7c-ef8dc5bf66d4
2023-04-04 14:46:24,908 - distributed.worker - INFO - Starting Worker plugin RMMSetup-fec5ef6a-bcdd-4d36-8763-a6df1ce8845c
2023-04-04 14:46:25,055 - distributed.worker - INFO - Starting Worker plugin CPUAffinity-2e37abeb-0ce9-4a05-8679-f2e97c69ba19
2023-04-04 14:46:25,056 - distributed.worker - INFO - Starting Worker plugin PreImport-61202e14-4f78-4d23-8460-b35cfa5f1bd6
2023-04-04 14:46:25,057 - distributed.worker - INFO - -------------------------------------------------
2023-04-04 14:46:25,084 - distributed.worker - INFO - -------------------------------------------------
2023-04-04 14:46:25,087 - distributed.worker - INFO -         Registered to:   tcp://10.120.104.11:8786
2023-04-04 14:46:25,087 - distributed.worker - INFO - -------------------------------------------------
2023-04-04 14:46:25,090 - distributed.core - INFO - Starting established connection to tcp://10.120.104.11:8786
2023-04-04 14:46:25,096 - distributed.worker - INFO -         Registered to:   tcp://10.120.104.11:8786
2023-04-04 14:46:25,096 - distributed.worker - INFO - -------------------------------------------------
2023-04-04 14:46:25,098 - distributed.core - INFO - Starting established connection to tcp://10.120.104.11:8786
2023-04-04 14:46:44,629 - distributed.worker - INFO - Run out-of-band function '_func_ucp_listener_port'
2023-04-04 14:46:44,632 - distributed.worker - INFO - Run out-of-band function '_func_ucp_listener_port'
2023-04-04 14:46:45,462 - distributed.worker - INFO - Run out-of-band function '_func_init_all'
2023-04-04 14:46:45,462 - distributed.worker - INFO - Run out-of-band function '_func_init_all'
2023-04-04 14:46:46,101 - distributed.worker - INFO - Run out-of-band function '_func_ucp_listener_port'
2023-04-04 14:46:46,120 - distributed.worker - INFO - Run out-of-band function '_func_ucp_listener_port'
2023-04-04 14:46:46,126 - distributed.worker - INFO - Run out-of-band function '_func_init_all'
2023-04-04 14:46:46,130 - distributed.worker - INFO - Run out-of-band function '_func_init_all'
2023-04-04 14:46:54,614 - distributed.worker - INFO - Run out-of-band function '_subcomm_init'
2023-04-04 14:46:54,835 - distributed.worker - INFO - Run out-of-band function '_subcomm_init'
2023-04-04 14:47:01,594 - distributed.core - INFO - Event loop was unresponsive in Worker for 15.28s.  This is often caused by long-running GIL-holding functions or moving large chunks of data. This can cause timeouts and instability.
2023-04-04 14:47:01,594 - distributed.core - INFO - Event loop was unresponsive in Worker for 15.28s.  This is often caused by long-running GIL-holding functions or moving large chunks of data. This can cause timeouts and instability.
2023-04-04 14:47:01,600 - distributed.worker - INFO - Run out-of-band function '_subcomm_init'
2023-04-04 14:47:01,600 - distributed.worker - INFO - Run out-of-band function '_subcomm_init'
2023-04-04 14:47:11,541 - distributed.worker - INFO - Run out-of-band function '_func_ucp_listener_port'
2023-04-04 14:47:11,542 - distributed.worker - INFO - Run out-of-band function '_func_ucp_listener_port'
2023-04-04 14:47:33,876 - distributed.worker - INFO - Stopping worker at tcp://10.120.104.11:34103. Reason: worker-handle-scheduler-connection-broken
2023-04-04 14:47:33,876 - distributed.worker - INFO - Stopping worker at tcp://10.120.104.11:41005. Reason: worker-handle-scheduler-connection-broken
2023-04-04 14:47:33,878 - distributed.nanny - INFO - Closing Nanny at 'tcp://10.120.104.11:37157'. Reason: nanny-close
2023-04-04 14:47:33,879 - distributed.nanny - INFO - Nanny asking worker to close. Reason: nanny-close
2023-04-04 14:47:33,881 - distributed.nanny - INFO - Closing Nanny at 'tcp://10.120.104.11:43933'. Reason: nanny-close
2023-04-04 14:47:33,883 - distributed.nanny - INFO - Nanny asking worker to close. Reason: nanny-close
2023-04-04 14:47:33,896 - distributed.worker - ERROR - Timed out during handshake while connecting to tcp://10.120.104.11:37157 after 100 s
Traceback (most recent call last):
  File "/opt/conda/envs/rapids/lib/python3.10/asyncio/runners.py", line 44, in run
    return loop.run_until_complete(main)
  File "/opt/conda/envs/rapids/lib/python3.10/asyncio/base_events.py", line 636, in run_until_complete
    self.run_forever()
  File "/opt/conda/envs/rapids/lib/python3.10/asyncio/base_events.py", line 603, in run_forever
    self._run_once()
  File "/opt/conda/envs/rapids/lib/python3.10/asyncio/base_events.py", line 1868, in _run_once
    event_list = self._selector.select(timeout)
  File "/opt/conda/envs/rapids/lib/python3.10/selectors.py", line 469, in select
    fd_event_list = self._selector.poll(timeout, max_ev)
KeyboardInterrupt

During handling of the above exception, another exception occurred:

Traceback (most recent call last):
  File "/opt/conda/envs/rapids/lib/python3.10/site-packages/tornado/iostream.py", line 869, in _read_to_buffer
    bytes_read = self.read_from_fd(buf)
  File "/opt/conda/envs/rapids/lib/python3.10/site-packages/tornado/iostream.py", line 1138, in read_from_fd
    return self.socket.recv_into(buf, len(buf))
ConnectionResetError: [Errno 104] Connection reset by peer

The above exception was the direct cause of the following exception:

Traceback (most recent call last):
  File "/opt/conda/envs/rapids/lib/python3.10/site-packages/distributed/comm/core.py", line 329, in connect
    handshake = await wait_for(comm.read(), time_left())
  File "/opt/conda/envs/rapids/lib/python3.10/site-packages/distributed/utils.py", line 1849, in wait_for
    return await asyncio.wait_for(fut, timeout)
  File "/opt/conda/envs/rapids/lib/python3.10/asyncio/tasks.py", line 445, in wait_for
    return fut.result()
  File "/opt/conda/envs/rapids/lib/python3.10/site-packages/distributed/comm/tcp.py", line 241, in read
    convert_stream_closed_error(self, e)
  File "/opt/conda/envs/rapids/lib/python3.10/site-packages/distributed/comm/tcp.py", line 142, in convert_stream_closed_error
    raise CommClosedError(f"in {obj}: {exc.__class__.__name__}: {exc}") from exc
distributed.comm.core.CommClosedError: in <TCP (closed)  local=tcp://10.120.104.11:38236 remote=tcp://10.120.104.11:37157>: ConnectionResetError: [Errno 104] Connection reset by peer

The above exception was the direct cause of the following exception:

Traceback (most recent call last):
  File "/opt/conda/envs/rapids/lib/python3.10/site-packages/distributed/utils.py", line 752, in wrapper
    return await func(*args, **kwargs)
  File "/opt/conda/envs/rapids/lib/python3.10/site-packages/distributed/worker.py", line 1573, in close
    await r.close_gracefully(reason=reason)
  File "/opt/conda/envs/rapids/lib/python3.10/site-packages/distributed/core.py", line 1262, in send_recv_from_rpc
    comm = await self.pool.connect(self.addr)
  File "/opt/conda/envs/rapids/lib/python3.10/site-packages/distributed/core.py", line 1506, in connect
    return await connect_attempt
  File "/opt/conda/envs/rapids/lib/python3.10/site-packages/distributed/core.py", line 1427, in _connect
    comm = await connect(
  File "/opt/conda/envs/rapids/lib/python3.10/site-packages/distributed/comm/core.py", line 334, in connect
    raise OSError(
OSError: Timed out during handshake while connecting to tcp://10.120.104.11:37157 after 100 s
2023-04-04 14:47:33,903 - distributed.worker - ERROR - Timed out during handshake while connecting to tcp://10.120.104.11:43933 after 100 s
Traceback (most recent call last):
  File "/opt/conda/envs/rapids/lib/python3.10/asyncio/runners.py", line 44, in run
    return loop.run_until_complete(main)
  File "/opt/conda/envs/rapids/lib/python3.10/asyncio/base_events.py", line 636, in run_until_complete
    self.run_forever()
  File "/opt/conda/envs/rapids/lib/python3.10/asyncio/base_events.py", line 603, in run_forever
    self._run_once()
  File "/opt/conda/envs/rapids/lib/python3.10/asyncio/base_events.py", line 1868, in _run_once
    event_list = self._selector.select(timeout)
  File "/opt/conda/envs/rapids/lib/python3.10/selectors.py", line 469, in select
    fd_event_list = self._selector.poll(timeout, max_ev)
KeyboardInterrupt

During handling of the above exception, another exception occurred:

Traceback (most recent call last):
  File "/opt/conda/envs/rapids/lib/python3.10/site-packages/tornado/iostream.py", line 869, in _read_to_buffer
    bytes_read = self.read_from_fd(buf)
  File "/opt/conda/envs/rapids/lib/python3.10/site-packages/tornado/iostream.py", line 1138, in read_from_fd
    return self.socket.recv_into(buf, len(buf))
ConnectionResetError: [Errno 104] Connection reset by peer

The above exception was the direct cause of the following exception:

Traceback (most recent call last):
  File "/opt/conda/envs/rapids/lib/python3.10/site-packages/distributed/comm/core.py", line 329, in connect
    handshake = await wait_for(comm.read(), time_left())
  File "/opt/conda/envs/rapids/lib/python3.10/site-packages/distributed/utils.py", line 1849, in wait_for
    return await asyncio.wait_for(fut, timeout)
  File "/opt/conda/envs/rapids/lib/python3.10/asyncio/tasks.py", line 445, in wait_for
    return fut.result()
  File "/opt/conda/envs/rapids/lib/python3.10/site-packages/distributed/comm/tcp.py", line 241, in read
    convert_stream_closed_error(self, e)
  File "/opt/conda/envs/rapids/lib/python3.10/site-packages/distributed/comm/tcp.py", line 142, in convert_stream_closed_error
    raise CommClosedError(f"in {obj}: {exc.__class__.__name__}: {exc}") from exc
distributed.comm.core.CommClosedError: in <TCP (closed)  local=tcp://10.120.104.11:46224 remote=tcp://10.120.104.11:43933>: ConnectionResetError: [Errno 104] Connection reset by peer

The above exception was the direct cause of the following exception:

Traceback (most recent call last):
  File "/opt/conda/envs/rapids/lib/python3.10/site-packages/distributed/utils.py", line 752, in wrapper
    return await func(*args, **kwargs)
  File "/opt/conda/envs/rapids/lib/python3.10/site-packages/distributed/worker.py", line 1573, in close
    await r.close_gracefully(reason=reason)
  File "/opt/conda/envs/rapids/lib/python3.10/site-packages/distributed/core.py", line 1262, in send_recv_from_rpc
    comm = await self.pool.connect(self.addr)
  File "/opt/conda/envs/rapids/lib/python3.10/site-packages/distributed/core.py", line 1506, in connect
    return await connect_attempt
  File "/opt/conda/envs/rapids/lib/python3.10/site-packages/distributed/core.py", line 1427, in _connect
    comm = await connect(
  File "/opt/conda/envs/rapids/lib/python3.10/site-packages/distributed/comm/core.py", line 334, in connect
    raise OSError(
OSError: Timed out during handshake while connecting to tcp://10.120.104.11:43933 after 100 s
2023-04-04 14:47:37,084 - distributed.nanny - WARNING - Worker process still alive after 3.199987030029297 seconds, killing
2023-04-04 14:47:37,084 - distributed.nanny - WARNING - Worker process still alive after 3.1999990844726565 seconds, killing
2023-04-04 14:47:37,881 - distributed.nanny - ERROR - Error in Nanny killing Worker subprocess
Traceback (most recent call last):
  File "/opt/conda/envs/rapids/lib/python3.10/asyncio/tasks.py", line 456, in wait_for
    return fut.result()
asyncio.exceptions.CancelledError

The above exception was the direct cause of the following exception:

Traceback (most recent call last):
  File "/opt/conda/envs/rapids/lib/python3.10/site-packages/distributed/nanny.py", line 607, in close
    await self.kill(timeout=timeout, reason=reason)
  File "/opt/conda/envs/rapids/lib/python3.10/site-packages/distributed/nanny.py", line 390, in kill
    await self.process.kill(reason=reason, timeout=0.8 * (deadline - time()))
  File "/opt/conda/envs/rapids/lib/python3.10/site-packages/distributed/nanny.py", line 844, in kill
    await process.join(max(0, deadline - time()))
  File "/opt/conda/envs/rapids/lib/python3.10/site-packages/distributed/process.py", line 330, in join
    await wait_for(asyncio.shield(self._exit_future), timeout)
  File "/opt/conda/envs/rapids/lib/python3.10/site-packages/distributed/utils.py", line 1849, in wait_for
    return await asyncio.wait_for(fut, timeout)
  File "/opt/conda/envs/rapids/lib/python3.10/asyncio/tasks.py", line 458, in wait_for
    raise exceptions.TimeoutError() from exc
asyncio.exceptions.TimeoutError
2023-04-04 14:47:37,884 - distributed.nanny - ERROR - Error in Nanny killing Worker subprocess
Traceback (most recent call last):
  File "/opt/conda/envs/rapids/lib/python3.10/asyncio/tasks.py", line 456, in wait_for
    return fut.result()
asyncio.exceptions.CancelledError

The above exception was the direct cause of the following exception:

Traceback (most recent call last):
  File "/opt/conda/envs/rapids/lib/python3.10/site-packages/distributed/nanny.py", line 607, in close
    await self.kill(timeout=timeout, reason=reason)
  File "/opt/conda/envs/rapids/lib/python3.10/site-packages/distributed/nanny.py", line 390, in kill
    await self.process.kill(reason=reason, timeout=0.8 * (deadline - time()))
  File "/opt/conda/envs/rapids/lib/python3.10/site-packages/distributed/nanny.py", line 844, in kill
    await process.join(max(0, deadline - time()))
  File "/opt/conda/envs/rapids/lib/python3.10/site-packages/distributed/process.py", line 330, in join
    await wait_for(asyncio.shield(self._exit_future), timeout)
  File "/opt/conda/envs/rapids/lib/python3.10/site-packages/distributed/utils.py", line 1849, in wait_for
    return await asyncio.wait_for(fut, timeout)
  File "/opt/conda/envs/rapids/lib/python3.10/asyncio/tasks.py", line 458, in wait_for
    raise exceptions.TimeoutError() from exc
asyncio.exceptions.TimeoutError
2023-04-04 14:47:37,886 - distributed.process - INFO - reaping stray process <SpawnProcess name='Dask Worker process (from Nanny)' pid=1325608 parent=1325580 started daemon>
2023-04-04 14:47:37,886 - distributed.process - INFO - reaping stray process <SpawnProcess name='Dask Worker process (from Nanny)' pid=1325605 parent=1325580 started daemon>
2023-04-04 14:47:38,385 - distributed.process - WARNING - [<AsyncProcess Dask Worker process (from Nanny)>] process 1325605 exit status was already read will report exitcode 255
